File: raw-data/glass_1_Sp15_245L_sect-001_group-1_glass.raw
#"Test Type","Manual"
#"Method Name:","C:\INSTRON\user\template\245L-Mod01.mtM"
#"Name:","4FtPerMin"
#"Operator ID:","Jaques"
#"Company:","BSU"
#"Lab name:",""
#"Test date:","1/26/15"
#"Temperature:",""
#"Humidity:",""
#"Note 1:",""
#"Note 2:",""
#"Note 3:",""
#"Geometry:","Circular"
#"Specimen",1
#"Specimen name:",""
#"Width:",6.350000,"mm"
#"Thickness:",1.524000,"mm"
#"Length:",12.000000,"mm"
#"Diameter:",5.000000,"um"
#"Inner diameter:",0.500000,"mm"
#"Outer diameter:",1.000000,"mm"
#"Wall thickness:",0.500000,"mm"
#"Area:",19.634954,"um*um"
#"Linear density:",1.000000,"den"
#"Sled weight:",9.806650,"N"
#"Loading span:",0.000000,"mm"
#"Support span:",1.000000,"mm"
#"Span ratio:","2"
#"Fixture type:","3-point"
#"Comment:",""
#"Included"
#"Time sec","Extension mm","Load N","Stress MPa","Cycle Count ","Total Cycle Count ","Repetitions Count ","Strain [Exten.] %","Tenacity gf/tex"
0,0,-4.687013,-238707.6,0,0,0,0,-4301.48
0.008,0,-4.655094,-237082,0,0,0,0,-4272.187
0.016,0,-4.628864,-235746.1,0,0,0,0,-4248.115
0.038,0,-4.627151,-235658.9,0,0,0,0,-4246.543
0.05,0,-4.656205,-237138.6,0,0,0,0,-4273.208
0.062,0,-4.682624,-238484.1,0,0,0,0,-4297.453
0.106,-0.000236111,-4.677679,-238232.2,0,0,0,-0.001967592,-4292.915
0.12,-0.000236111,-4.655532,-237104.3,0,0,0,-0.001967592,-4272.589
0.136,-0.000236111,-4.678642,-238281.3,0,0,0,-0.001967592,-4293.799
0.144,-0.000236111,-4.708138,-239783.5,0,0,0,-0.001967592,-4320.868
0.152,-0.000236111,-4.740103,-241411.5,0,0,0,-0.001967592,-4350.204
0.16,-0.000236111,-4.765731,-242716.7,0,0,0,-0.001967592,-4373.724
0.168,-0.000472222,-4.786758,-243787.6,0,0,0,-0.003935183,-4393.021
0.18,-0.000472222,-4.812752,-245111.5,0,0,0,-0.003935183,-4416.877
0.218,-0.0007083331,-4.823259,-245646.5,0,0,0,-0.005902776,-4426.52
0.228,-0.0007083331,-4.855146,-247270.6,0,0,0,-0.005902776,-4455.784
0.232,-0.0007083331,-4.877906,-248429.7,0,0,0,-0.005902776,-4476.672
0.236,-0.0007083331,-4.902983,-249706.9,0,0,0,-0.005902776,-4499.686
0.24,-0.0007083331,-4.928245,-250993.5,0,0,0,-0.005902776,-4522.871
0.244,-0.0007083331,-4.952009,-252203.8,0,0,0,-0.005902776,-4544.679
0.25,-0.0007083331,-4.980544,-253657,0,0,0,-0.005902776,-4570.867
0.26,-0.000944444,-5.007051,-255007,0,0,0,-0.007870367,-4595.194
0.284,-0.001180555,-5.026045,-255974.4,0,0,0,-0.009837959,-4612.625
0.302,-0.001180555,-5.047693,-257076.9,0,0,0,-0.009837959,-4632.493
0.328,-0.001416666,-5.056908,-257546.2,0,0,0,-0.01180555,-4640.95
0.338,-0.001416666,-5.081112,-258778.9,0,0,0,-0.01180555,-4663.163
0.348,-0.001652777,-5.104023,-259945.8,0,0,0,-0.01377314,-4684.19
0.37,-0.001652777,-5.127995,-261166.6,0,0,0,-0.01377314,-4706.189
0.38,-0.001888888,-5.142164,-261888.3,0,0,0,-0.01574073,-4719.193
0.392,-0.001888888,-5.165814,-263092.8,0,0,0,-0.01574073,-4740.898
0.404,-0.002124999,-5.184956,-264067.6,0,0,0,-0.01770833,-4758.465
0.432,-0.002124999,-5.206348,-265157.1,0,0,0,-0.01770833,-4778.098
0.446,-0.002124999,-5.230071,-266365.3,0,0,0,-0.01770833,-4799.869
0.47,-0.00236111,-5.220283,-265866.8,0,0,0,-0.01967592,-4790.886
0.498,-0.00236111,-5.221845,-265946.4,0,0,0,-0.01967592,-4792.32
0.508,-0.002597221,-5.236218,-266678.4,0,0,0,-0.02164351,-4805.511
0.518,-0.002597221,-5.25994,-267886.6,0,0,0,-0.02164351,-4827.282
0.526,-0.002833332,-5.282622,-269041.7,0,0,0,-0.0236111,-4848.098
0.534,-0.002833332,-5.309397,-270405.4,0,0,0,-0.0236111,-4872.671
0.54,-0.003069443,-5.328444,-271375.4,0,0,0,-0.02557869,-4890.151
0.548,-0.003069443,-5.354459,-272700.4,0,0,0,-0.02557869,-4914.026
0.556,-0.003305554,-5.379292,-273965.1,0,0,0,-0.02754628,-4936.816
0.564,-0.003305554,-5.401105,-275076,0,0,0,-0.02754628,-4956.835
0.572,-0.003541665,-5.419472,-276011.4,0,0,0,-0.02951388,-4973.691
0.582,-0.003777776,-5.43825,-276967.8,0,0,0,-0.03148147,-4990.924
0.592,-0.003777776,-5.463663,-278262.1,0,0,0,-0.03148147,-5014.247
0.6,-0.004013887,-5.488324,-279518.1,0,0,0,-0.03344906,-5036.88
0.608,-0.004013887,-5.515854,-280920.1,0,0,0,-0.03344906,-5062.145
0.616,-0.004249998,-5.544267,-282367.2,0,0,0,-0.03541665,-5088.221
0.624,-0.004249998,-5.569911,-283673.3,0,0,0,-0.03541665,-5111.756
0.63,-0.004486109,-5.585631,-284473.8,0,0,0,-0.03738425,-5126.183
0.638,-0.004486109,-5.606606,-285542.1,0,0,0,-0.03738425,-5145.432
0.644,-0.00472222,-5.624517,-286454.3,0,0,0,-0.03935184,-5161.87
0.652,-0.00472222,-5.648787,-287690.3,0,0,0,-0.03935184,-5184.144
0.66,-0.004958331,-5.671043,-288823.9,0,0,0,-0.04131943,-5204.569
0.668,-0.005194443,-5.692589,-289921.2,0,0,0,-0.04328702,-5224.342
0.676,-0.005194443,-5.713248,-290973.3,0,0,0,-0.04328702,-5243.302
0.684,-0.005430553,-5.733874,-292023.8,0,0,0,-0.04525461,-5262.231
0.692,-0.005430553,-5.757628,-293233.6,0,0,0,-0.04525461,-5284.032
0.698,-0.005666665,-5.777147,-294227.7,0,0,0,-0.0472222,-5301.945
0.706,-0.005666665,-5.804184,-295604.7,0,0,0,-0.0472222,-5326.759
0.712,-0.005902775,-5.823206,-296573.5,0,0,0,-0.04918979,-5344.216
0.72,-0.005902775,-5.84618,-297743.5,0,0,0,-0.04918979,-5365.3
0.728,-0.006138886,-5.865028,-298703.4,0,0,0,-0.05115739,-5382.598
0.738,-0.006138886,-5.888072,-299877,0,0,0,-0.05115739,-5403.746
0.744,-0.006374997,-5.904926,-300735.4,0,0,0,-0.05312498,-5419.214
0.752,-0.006374997,-5.927174,-301868.5,0,0,0,-0.05312498,-5439.632
0.76,-0.006611108,-5.947125,-302884.6,0,0,0,-0.05509257,-5457.941
0.772,-0.006611108,-5.969014,-303999.4,0,0,0,-0.05509257,-5478.03
0.782,-0.00684722,-5.98831,-304982.1,0,0,0,-0.05706016,-5495.739
0.792,-0.00708333,-6.008567,-306013.8,0,0,0,-0.05902775,-5514.33
0.804,-0.00708333,-6.036093,-307415.7,0,0,0,-0.05902775,-5539.592
0.814,-0.007319441,-6.055115,-308384.5,0,0,0,-0.06099534,-5557.049
0.824,-0.007555552,-6.074974,-309395.9,0,0,0,-0.06296293,-5575.274
0.836,-0.007555552,-6.099825,-310661.6,0,0,0,-0.06296293,-5598.082
0.848,-0.007791664,-6.125382,-311963.1,0,0,0,-0.06493053,-5621.536
0.858,-0.008027775,-6.140667,-312741.6,0,0,0,-0.06689812,-5635.564
0.878,-0.008263885,-6.160111,-313731.9,0,0,0,-0.06886571,-5653.408
0.892,-0.008263885,-6.181735,-314833.2,0,0,0,-0.06886571,-5673.254
0.902,-0.008499997,-6.205691,-316053.3,0,0,0,-0.0708333,-5695.24
0.91,-0.008499997,-6.227487,-317163.3,0,0,0,-0.0708333,-5715.243
0.922,-0.008736108,-6.251385,-318380.4,0,0,0,-0.0728009,-5737.175
0.936,-0.008972219,-6.269889,-319322.8,0,0,0,-0.07476849,-5754.157
0.956,-0.00920833,-6.290127,-320353.5,0,0,0,-0.07673608,-5772.729
0.97,-0.00920833,-6.311283,-321431,0,0,0,-0.07673608,-5792.146
0.984,-0.00944444,-6.334482,-322612.5,0,0,0,-0.07870367,-5813.437
0.996,-0.009680551,-6.352743,-323542.5,0,0,0,-0.08067126,-5830.195
1.008,-0.009680551,-6.376563,-324755.7,0,0,0,-0.08067126,-5852.056
1.016,-0.009916663,-6.394619,-325675.3,0,0,0,-0.08263886,-5868.627
1.036,-0.01015277,-6.408569,-326385.8,0,0,0,-0.08460645,-5881.43
1.058,-0.01038889,-6.430272,-327491.1,0,0,0,-0.08657404,-5901.347
1.07,-0.01038889,-6.452527,-328624.5,0,0,0,-0.08657404,-5921.772
1.094,-0.010625,-6.474752,-329756.4,0,0,0,-0.08854163,-5942.169
1.104,-0.01086111,-6.489546,-330509.8,0,0,0,-0.09050922,-5955.745
1.116,-0.01086111,-6.512347,-331671.1,0,0,0,-0.09050922,-5976.671
1.15,-0.01133333,-6.530818,-332611.8,0,0,0,-0.09444441,-5993.623
1.162,-0.01133333,-6.555652,-333876.6,0,0,0,-0.09444441,-6016.414
1.174,-0.01156944,-6.572389,-334729,0,0,0,-0.096412,-6031.774
1.188,-0.01156944,-6.596711,-335967.8,0,0,0,-0.096412,-6054.096
1.196,-0.01180555,-6.614437,-336870.5,0,0,0,-0.09837959,-6070.364
1.208,-0.01180555,-6.639945,-338169.6,0,0,0,-0.09837959,-6093.773
1.218,-0.01204166,-6.653684,-338869.3,0,0,0,-0.1003472,-6106.383
1.244,-0.01227777,-6.674584,-339933.8,0,0,0,-0.1023148,-6125.564
1.266,-0.01251388,-6.695141,-340980.7,0,0,0,-0.1042824,-6144.429
1.29,-0.01274999,-6.71669,-342078.2,0,0,0,-0.10625,-6164.206
1.312,-0.01298611,-6.738316,-343179.6,0,0,0,-0.1082175,-6184.053
1.332,-0.01298611,-6.760267,-344297.6,0,0,0,-0.1082175,-6204.199
1.35,-0.01322222,-6.776228,-345110.5,0,0,0,-0.1101851,-6218.847
1.362,-0.01345833,-6.797233,-346180.3,0,0,0,-0.1121527,-6238.124
1.374,-0.01345833,-6.817947,-347235.2,0,0,0,-0.1121527,-6257.134
1.394,-0.01369444,-6.840812,-348399.7,0,0,0,-0.1141203,-6278.118
1.412,-0.01393055,-6.860283,-349391.4,0,0,0,-0.1160879,-6295.988
1.424,-0.01393055,-6.885119,-350656.3,0,0,0,-0.1160879,-6318.781
1.436,-0.01416666,-6.902996,-351566.7,0,0,0,-0.1180555,-6335.187
1.464,-0.01440277,-6.921325,-352500.2,0,0,0,-0.1200231,-6352.008
1.472,-0.01463888,-6.936457,-353270.9,0,0,0,-0.1219907,-6365.896
1.484,-0.01463888,-6.957904,-354363.2,0,0,0,-0.1219907,-6385.579
1.496,-0.01487499,-6.975371,-355252.8,0,0,0,-0.1239583,-6401.609
1.518,-0.0151111,-6.996044,-356305.6,0,0,0,-0.1259259,-6420.582
1.538,-0.0151111,-7.017547,-357400.7,0,0,0,-0.1259259,-6440.315
1.55,-0.01534721,-7.029925,-358031.2,0,0,0,-0.1278935,-6451.676
1.562,-0.01558333,-7.042785,-358686.1,0,0,0,-0.1298611,-6463.478
1.578,-0.01558333,-7.068436,-359992.5,0,0,0,-0.1298611,-6487.019
1.59,-0.01581944,-7.095947,-361393.6,0,0,0,-0.1318286,-6512.268
1.606,-0.01605555,-7.113486,-362286.9,0,0,0,-0.1337962,-6528.363
1.626,-0.01629166,-7.10478,-361843.5,0,0,0,-0.1357638,-6520.373
1.638,-0.01629166,-7.12708,-362979.2,0,0,0,-0.1357638,-6540.839
1.646,-0.01629166,-7.149308,-364111.3,0,0,0,-0.1357638,-6561.239
1.656,-0.01652777,-7.171256,-365229.1,0,0,0,-0.1377314,-6581.382
1.668,-0.01652777,-7.193538,-366363.9,0,0,0,-0.1377314,-6601.831
1.684,-0.01676388,-7.214198,-367416.1,0,0,0,-0.139699,-6620.791
1.698,-0.01699999,-7.230946,-368269.1,0,0,0,-0.1416666,-6636.162
1.72,-0.0172361,-7.24397,-368932.4,0,0,0,-0.1436342,-6648.114
1.752,-0.01747222,-7.263756,-369940.1,0,0,0,-0.1456018,-6666.272
1.764,-0.01747222,-7.28417,-370979.8,0,0,0,-0.1456018,-6685.008
1.772,-0.01770833,-7.305295,-372055.6,0,0,0,-0.1475694,-6704.395
1.782,-0.01770833,-7.329321,-373279.3,0,0,0,-0.1475694,-6726.445
1.794,-0.01794444,-7.342775,-373964.5,0,0,0,-0.149537,-6738.792
1.84,-0.01841666,-7.348629,-374262.6,0,0,0,-0.1534722,-6744.164
1.85,-0.01841666,-7.376182,-375665.9,0,0,0,-0.1534722,-6769.451
1.858,-0.01841666,-7.402439,-377003.1,0,0,0,-0.1534722,-6793.548
1.864,-0.01865277,-7.422129,-378005.9,0,0,0,-0.1554397,-6811.619
1.872,-0.01865277,-7.44374,-379106.6,0,0,0,-0.1554397,-6831.452
1.886,-0.01888888,-7.467602,-380321.8,0,0,0,-0.1574073,-6853.351
1.934,-0.0193611,-7.472004,-380546,0,0,0,-0.1613425,-6857.391
1.946,-0.0193611,-7.496944,-381816.3,0,0,0,-0.1613425,-6880.28
1.958,-0.01959721,-7.524644,-383227,0,0,0,-0.1633101,-6905.701
1.972,-0.01959721,-7.546891,-384360,0,0,0,-0.1633101,-6926.119
1.982,-0.01983333,-7.568117,-385441,0,0,0,-0.1652777,-6945.598
1.994,-0.01983333,-7.593541,-386735.9,0,0,0,-0.1652777,-6968.931
2.01,-0.02006944,-7.582196,-386158.1,0,0,0,-0.1672453,-6958.519
2.02,-0.02006944,-7.559321,-384993.1,0,0,0,-0.1672453,-6937.526
2.034,-0.02030555,-7.569274,-385500,0,0,0,-0.1692129,-6946.66
2.042,-0.02030555,-7.593216,-386719.3,0,0,0,-0.1692129,-6968.633
2.05,-0.02030555,-7.618004,-387981.8,0,0,0,-0.1692129,-6991.382
2.056,-0.02054166,-7.634864,-388840.4,0,0,0,-0.1711805,-7006.855
2.064,-0.02054166,-7.659788,-390109.8,0,0,0,-0.1711805,-7029.729
2.074,-0.02077777,-7.683315,-391308,0,0,0,-0.1731481,-7051.321
2.098,-0.02101388,-7.700278,-392172,0,0,0,-0.1751157,-7066.889
2.136,-0.02124999,-7.709613,-392647.4,0,0,0,-0.1770833,-7075.456
2.144,-0.0214861,-7.727346,-393550.5,0,0,0,-0.1790509,-7091.73
2.152,-0.0214861,-7.75414,-394915.1,0,0,0,-0.1790509,-7116.32
2.16,-0.0214861,-7.780392,-396252.1,0,0,0,-0.1790509,-7140.413
2.168,-0.02172221,-7.799451,-397222.8,0,0,0,-0.1810184,-7157.904
2.188,-0.02195833,-7.81031,-397775.8,0,0,0,-0.1829861,-7167.87
2.212,-0.02219444,-7.825782,-398563.8,0,0,0,-0.1849536,-7182.069
2.224,-0.02219444,-7.847269,-399658.1,0,0,0,-0.1849536,-7201.789
2.242,-0.02243054,-7.869001,-400764.9,0,0,0,-0.1869212,-7221.733
2.256,-0.02243054,-7.894776,-402077.6,0,0,0,-0.1869212,-7245.388
2.264,-0.02266666,-7.911339,-402921.2,0,0,0,-0.1888888,-7260.589
2.282,-0.02290277,-7.920891,-403407.7,0,0,0,-0.1908564,-7269.355
2.314,-0.02313888,-7.940814,-404422.3,0,0,0,-0.192824,-7287.639
2.328,-0.02313888,-7.964314,-405619.2,0,0,0,-0.192824,-7309.206
2.338,-0.02337499,-7.980593,-406448.3,0,0,0,-0.1947916,-7324.146
2.35,-0.02337499,-8.007019,-407794.1,0,0,0,-0.1947916,-7348.398
2.36,-0.0236111,-8.02567,-408744,0,0,0,-0.1967592,-7365.516
2.376,-0.02384721,-8.045081,-409732.6,0,0,0,-0.1987268,-7383.33
2.41,-0.02408332,-8.052767,-410124.1,0,0,0,-0.2006944,-7390.384
2.422,-0.02408332,-8.076407,-411328,0,0,0,-0.2006944,-7412.079
2.44,-0.02431944,-8.097723,-412413.7,0,0,0,-0.202662,-7431.642
2.454,-0.02455555,-8.109644,-413020.8,0,0,0,-0.2046295,-7442.582
2.474,-0.02455555,-8.130678,-414092,0,0,0,-0.2046295,-7461.886
2.488,-0.02479165,-8.146763,-414911.2,0,0,0,-0.2065971,-7476.647
2.5,-0.02479165,-8.169075,-416047.6,0,0,0,-0.2065971,-7497.125
2.51,-0.02502777,-8.19164,-417196.8,0,0,0,-0.2085647,-7517.833
2.528,-0.02526388,-8.213315,-418300.7,0,0,0,-0.2105323,-7537.726
2.552,-0.02549999,-8.230688,-419185.5,0,0,0,-0.2124999,-7553.669
2.57,-0.02549999,-8.253957,-420370.6,0,0,0,-0.2124999,-7575.024
2.58,-0.0257361,-8.271594,-421268.8,0,0,0,-0.2144675,-7591.21
2.596,-0.02597221,-8.292041,-422310.2,0,0,0,-0.2164351,-7609.976
2.614,-0.02597221,-8.313344,-423395.1,0,0,0,-0.2164351,-7629.526
2.63,-0.02620832,-8.33205,-424347.8,0,0,0,-0.2184027,-7646.694
2.644,-0.02644443,-8.349237,-425223.2,0,0,0,-0.2203703,-7662.467
2.67,-0.02668055,-8.371652,-426364.8,0,0,0,-0.2223379,-7683.039
2.684,-0.02668055,-8.394999,-427553.8,0,0,0,-0.2223379,-7704.465
2.696,-0.02691665,-8.409395,-428287,0,0,0,-0.2243055,-7717.677
2.718,-0.02715277,-8.42927,-429299.2,0,0,0,-0.2262731,-7735.917
2.736,-0.02715277,-8.450639,-430387.5,0,0,0,-0.2262731,-7755.528
2.752,-0.02738888,-8.467855,-431264.3,0,0,0,-0.2282407,-7771.328
2.776,-0.02762499,-8.489475,-432365.4,0,0,0,-0.2302082,-7791.169
2.788,-0.0278611,-8.508911,-433355.3,0,0,0,-0.2321758,-7809.007
2.8,-0.0278611,-8.531529,-434507.3,0,0,0,-0.2321758,-7829.765
2.812,-0.02809721,-8.550412,-435468.9,0,0,0,-0.2341434,-7847.094
2.828,-0.02809721,-8.57466,-436703.8,0,0,0,-0.2341434,-7869.348
2.85,-0.02833332,-8.594785,-437728.8,0,0,0,-0.236111,-7887.817
2.86,-0.02856943,-8.608754,-438440.3,0,0,0,-0.2380786,-7900.637
2.88,-0.02856943,-8.630812,-439563.7,0,0,0,-0.2380786,-7920.881
2.906,-0.02880554,-8.644469,-440259.2,0,0,0,-0.2400462,-7933.415
2.914,-0.02904166,-8.660727,-441087.2,0,0,0,-0.2420138,-7948.335
2.93,-0.02927776,-8.678104,-441972.2,0,0,0,-0.2439814,-7964.283
2.952,-0.02951388,-8.696207,-442894.2,0,0,0,-0.245949,-7980.897
2.968,-0.02951388,-8.718058,-444007,0,0,0,-0.245949,-8000.95
2.986,-0.02974999,-8.740104,-445129.8,0,0,0,-0.2479166,-8021.183
2.998,-0.02974999,-8.762334,-446262,0,0,0,-0.2479166,-8041.584
3.006,-0.0299861,-8.777377,-447028.2,0,0,0,-0.2498841,-8055.391
3.018,-0.0299861,-8.800921,-448227.3,0,0,0,-0.2498841,-8076.998
3.038,-0.03022221,-8.821133,-449256.6,0,0,0,-0.2518517,-8095.547
3.072,-0.03045832,-8.837904,-450110.8,0,0,0,-0.2538193,-8110.938
3.088,-0.03069443,-8.857726,-451120.3,0,0,0,-0.2557869,-8129.13
3.106,-0.03093054,-8.880972,-452304.2,0,0,0,-0.2577545,-8150.464
3.124,-0.03093054,-8.906203,-453589.2,0,0,0,-0.2577545,-8173.62
3.138,-0.03116666,-8.928422,-454720.8,0,0,0,-0.2597221,-8194.011
3.178,-0.03163887,-8.943317,-455479.4,0,0,0,-0.2636573,-8207.681
3.188,-0.03163887,-8.966664,-456668.4,0,0,0,-0.2636573,-8229.107
3.198,-0.03163887,-8.991002,-457908,0,0,0,-0.2636573,-8251.443
3.206,-0.03187499,-9.005543,-458648.5,0,0,0,-0.2656249,-8264.788
3.234,-0.0321111,-9.025737,-459677,0,0,0,-0.2675925,-8283.321
3.262,-0.03234721,-9.048244,-460823.3,0,0,0,-0.2695601,-8303.977
3.278,-0.03258332,-9.069816,-461922,0,0,0,-0.2715277,-8323.774
3.292,-0.03258332,-9.093083,-463106.9,0,0,0,-0.2715277,-8345.128
3.304,-0.03281943,-9.108854,-463910.1,0,0,0,-0.2734953,-8359.601
3.318,-0.03281943,-9.13353,-465166.9,0,0,0,-0.2734953,-8382.248
3.326,-0.03305554,-9.147878,-465897.6,0,0,0,-0.2754628,-8395.415
3.342,-0.03329165,-9.163612,-466698.9,0,0,0,-0.2774304,-8409.854
3.366,-0.03352777,-9.183863,-467730.3,0,0,0,-0.2793981,-8428.44
3.388,-0.03352777,-9.206343,-468875.2,0,0,0,-0.2793981,-8449.072
3.404,-0.03376387,-9.219916,-469566.5,0,0,0,-0.2813656,-8461.527
3.42,-0.03399999,-9.241453,-470663.4,0,0,0,-0.2833332,-8481.294
3.434,-0.0342361,-9.263488,-471785.6,0,0,0,-0.2853008,-8501.517
3.456,-0.03447221,-9.283908,-472825.5,0,0,0,-0.2872684,-8520.256
3.472,-0.03447221,-9.308184,-474061.9,0,0,0,-0.2872684,-8542.536
3.488,-0.03470832,-9.329032,-475123.7,0,0,0,-0.289236,-8561.669
3.502,-0.03494443,-9.34351,-475861.1,0,0,0,-0.2912036,-8574.956
3.518,-0.03494443,-9.368084,-477112.6,0,0,0,-0.2912036,-8597.509
3.532,-0.03518054,-9.390327,-478245.4,0,0,0,-0.2931712,-8617.922
3.548,-0.03541665,-9.403966,-478940.1,0,0,0,-0.2951388,-8630.439
3.572,-0.03565276,-9.426315,-480078.3,0,0,0,-0.2971064,-8650.95
3.596,-0.03565276,-9.448457,-481205.9,0,0,0,-0.2971064,-8671.27
3.608,-0.03588887,-9.462187,-481905.3,0,0,0,-0.299074,-8683.871
3.618,-0.03612498,-9.487614,-483200.2,0,0,0,-0.3010415,-8707.206
3.63,-0.03612498,-9.512407,-484462.9,0,0,0,-0.3010415,-8729.96
3.644,-0.0363611,-9.527522,-485232.7,0,0,0,-0.3030091,-8743.832
3.66,-0.0363611,-9.549617,-486358,0,0,0,-0.3030091,-8764.109
3.68,-0.03659721,-9.565021,-487142.5,0,0,0,-0.3049767,-8778.246
3.698,-0.03683332,-9.586242,-488223.3,0,0,0,-0.3069443,-8797.722
3.71,-0.03683332,-9.607685,-489315.4,0,0,0,-0.3069443,-8817.4
3.736,-0.03730554,-9.621535,-490020.8,0,0,0,-0.3108795,-8830.112
3.76,-0.03754165,-9.636332,-490774.4,0,0,0,-0.3128471,-8843.691
3.772,-0.03754165,-9.658517,-491904.3,0,0,0,-0.3128471,-8864.052
3.782,-0.03777776,-9.673491,-492666.9,0,0,0,-0.3148147,-8877.794
3.798,-0.03777776,-9.695525,-493789.1,0,0,0,-0.3148147,-8898.016
3.814,-0.03801387,-9.716175,-494840.8,0,0,0,-0.3167823,-8916.968
3.83,-0.03824999,-9.739243,-496015.6,0,0,0,-0.3187499,-8938.138
3.848,-0.03824999,-9.761157,-497131.6,0,0,0,-0.3187499,-8958.249
3.862,-0.0384861,-9.775587,-497866.6,0,0,0,-0.3207175,-8971.492
3.876,-0.03872221,-9.790118,-498606.6,0,0,0,-0.322685,-8984.828
3.894,-0.03872221,-9.81071,-499655.4,0,0,0,-0.322685,-9003.727
3.912,-0.03895832,-9.829913,-500633.4,0,0,0,-0.3246527,-9021.35
3.926,-0.03919443,-9.851795,-501747.8,0,0,0,-0.3266203,-9041.432
3.946,-0.03919443,-9.873235,-502839.7,0,0,0,-0.3266203,-9061.107
3.96,-0.03943054,-9.887089,-503545.3,0,0,0,-0.3285878,-9073.822
3.978,-0.03966665,-9.905793,-504497.9,0,0,0,-0.3305554,-9090.987
3.994,-0.03966665,-9.929973,-505729.4,0,0,0,-0.3305554,-9113.179
4.002,-0.03990276,-9.943199,-506403,0,0,0,-0.332523,-9125.317
4.026,-0.04013887,-9.958873,-507201.2,0,0,0,-0.3344906,-9139.701
4.05,-0.04013887,-9.979434,-508248.4,0,0,0,-0.3344906,-9158.572
4.06,-0.04037498,-9.992147,-508895.9,0,0,0,-0.3364582,-9170.238
4.074,-0.04061109,-10.00935,-509772,0,0,0,-0.3384258,-9186.026
4.092,-0.04061109,-10.03193,-510922.3,0,0,0,-0.3384258,-9206.754
4.104,-0.0408472,-10.04785,-511733,0,0,0,-0.3403934,-9221.363
4.116,-0.0408472,-10.07053,-512887.7,0,0,0,-0.3403934,-9242.17
4.134,-0.04108332,-10.08735,-513744.4,0,0,0,-0.342361,-9257.609
4.152,-0.04131943,-10.10752,-514771.7,0,0,0,-0.3443286,-9276.121
4.166,-0.04131943,-10.12987,-515909.8,0,0,0,-0.3443286,-9296.63
4.18,-0.04155554,-10.14262,-516559.6,0,0,0,-0.3462962,-9308.338
4.206,-0.04179165,-10.15914,-517401,0,0,0,-0.3482637,-9323.5
4.216,-0.04202776,-10.18073,-518500.4,0,0,0,-0.3502313,-9343.312
4.24,-0.04226387,-10.20094,-519529.8,0,0,0,-0.3521989,-9361.86
4.264,-0.04249998,-10.22352,-520679.6,0,0,0,-0.3541665,-9382.58
4.276,-0.04249998,-10.24546,-521796.9,0,0,0,-0.3541665,-9402.713
4.286,-0.04273609,-10.25967,-522520.7,0,0,0,-0.3561341,-9415.757
4.302,-0.04273609,-10.28092,-523603,0,0,0,-0.3561341,-9435.259
4.324,-0.04297221,-10.30054,-524602.3,0,0,0,-0.3581017,-9453.266
4.342,-0.04320832,-10.32619,-525908.8,0,0,0,-0.3600693,-9476.809
4.356,-0.04344442,-10.34987,-527114.4,0,0,0,-0.3620369,-9498.533
4.37,-0.04344442,-10.37069,-528175.1,0,0,0,-0.3620369,-9517.647
4.38,-0.04368054,-10.38434,-528870.1,0,0,0,-0.3640045,-9530.171
4.396,-0.04368054,-10.40749,-530049.4,0,0,0,-0.3640045,-9551.422
4.43,-0.04415276,-10.40468,-529906.1,0,0,0,-0.3679397,-9548.84
4.446,-0.04415276,-10.42806,-531096.8,0,0,0,-0.3679397,-9570.297
4.454,-0.04438887,-10.44321,-531868.2,0,0,0,-0.3699073,-9584.197
4.464,-0.04438887,-10.46666,-533062.6,0,0,0,-0.3699073,-9605.72
4.476,-0.04462499,-10.49204,-534355.2,0,0,0,-0.3718749,-9629.012
4.488,-0.04462499,-10.51396,-535471.7,0,0,0,-0.3718749,-9649.131
4.5,-0.04486109,-10.52791,-536182,0,0,0,-0.3738424,-9661.932
4.542,-0.0450972,-10.53371,-536477.3,0,0,0,-0.37581,-9667.253
4.55,-0.04533332,-10.54919,-537266.1,0,0,0,-0.3777776,-9681.466
4.562,-0.04533332,-10.57733,-538699,0,0,0,-0.3777776,-9707.287
4.572,-0.04556942,-10.59963,-539834.8,0,0,0,-0.3797452,-9727.753
4.588,-0.04556942,-10.62126,-540936.2,0,0,0,-0.3797452,-9747.602
4.612,-0.04580554,-10.63717,-541746.4,0,0,0,-0.3817128,-9762.201
4.63,-0.04604165,-10.65536,-542673.1,0,0,0,-0.3836804,-9778.9
4.642,-0.04627776,-10.66996,-543416.5,0,0,0,-0.385648,-9792.296
4.656,-0.04627776,-10.69372,-544626.8,0,0,0,-0.385648,-9814.104
4.666,-0.04651387,-10.71213,-545564.5,0,0,0,-0.3876156,-9831.003
4.678,-0.04651387,-10.73439,-546698.2,0,0,0,-0.3876156,-9851.433
4.712,-0.04698609,-10.74843,-547413.1,0,0,0,-0.3915508,-9864.314
4.73,-0.04698609,-10.77063,-548543.5,0,0,0,-0.3915508,-9884.685
4.744,-0.0472222,-10.79275,-549670.3,0,0,0,-0.3935184,-9904.988
4.756,-0.0472222,-10.81531,-550819,0,0,0,-0.3935184,-9925.688
4.764,-0.04745831,-10.83062,-551599.2,0,0,0,-0.3954859,-9939.747
4.776,-0.04745831,-10.85483,-552832.2,0,0,0,-0.3954859,-9961.966
4.792,-0.04769443,-10.87319,-553767.1,0,0,0,-0.3974535,-9978.813
4.806,-0.04793053,-10.88528,-554382.6,0,0,0,-0.3994211,-9989.903
4.83,-0.04793053,-10.90577,-555426.4,0,0,0,-0.3994211,-10008.71
4.856,-0.04840276,-10.91831,-556064.8,0,0,0,-0.4033563,-10020.22
4.868,-0.04840276,-10.9446,-557404.1,0,0,0,-0.4033563,-10044.35
4.88,-0.04863887,-10.96287,-558334.5,0,0,0,-0.4053239,-10061.12
4.914,-0.04887498,-10.98303,-559361.1,0,0,0,-0.4072915,-10079.62
4.928,-0.04911109,-11.00276,-560365.9,0,0,0,-0.4092591,-10097.72
4.946,-0.04911109,-11.02813,-561658.1,0,0,0,-0.4092591,-10121.01
4.956,-0.0493472,-11.05171,-562859.1,0,0,0,-0.4112267,-10142.65
4.964,-0.0493472,-11.07343,-563965.1,0,0,0,-0.4112267,-10162.58
4.974,-0.04958331,-11.09207,-564914.7,0,0,0,-0.4131942,-10179.69
4.998,-0.04981942,-11.11182,-565920.4,0,0,0,-0.4151618,-10197.81
5.02,-0.05005554,-11.12968,-566829.8,0,0,0,-0.4171295,-10214.2
5.042,-0.05029164,-11.154,-568068.8,0,0,0,-0.419097,-10236.53
5.052,-0.05029164,-11.17753,-569267.1,0,0,0,-0.419097,-10258.12
5.062,-0.05029164,-11.20043,-570433.3,0,0,0,-0.419097,-10279.14
5.072,-0.05052776,-11.21426,-571137.8,0,0,0,-0.4210646,-10291.83
5.086,-0.05076387,-11.22906,-571891.5,0,0,0,-0.4230323,-10305.41
5.108,-0.05076387,-11.25106,-573011.8,0,0,0,-0.4230323,-10325.6
5.124,-0.05099998,-11.26434,-573688.1,0,0,0,-0.4249998,-10337.79
5.134,-0.05123609,-11.27794,-574380.8,0,0,0,-0.4269674,-10350.27
5.15,-0.05123609,-11.30086,-575548.1,0,0,0,-0.4269674,-10371.3
5.166,-0.0514722,-11.32024,-576535,0,0,0,-0.428935,-10389.09
5.182,-0.05170831,-11.34143,-577614.1,0,0,0,-0.4309026,-10408.53
5.202,-0.05170831,-11.36367,-578746.9,0,0,0,-0.4309026,-10428.95
5.218,-0.05194442,-11.37571,-579360,0,0,0,-0.4328702,-10439.99
5.234,-0.05218054,-11.393,-580240.8,0,0,0,-0.4348378,-10455.86
5.246,-0.05218054,-11.41893,-581561.2,0,0,0,-0.4348378,-10479.66
5.258,-0.05241664,-11.44494,-582886.2,0,0,0,-0.4368054,-10503.53
5.27,-0.05241664,-11.46953,-584138.1,0,0,0,-0.4368054,-10526.09
5.286,-0.05265275,-11.486,-584977.3,0,0,0,-0.4387729,-10541.22
5.308,-0.05288887,-11.50226,-585805.6,0,0,0,-0.4407406,-10556.14
5.322,-0.05312498,-11.5152,-586464.4,0,0,0,-0.4427081,-10568.01
5.348,-0.05336109,-11.528,-587116.3,0,0,0,-0.4446757,-10579.76
5.368,-0.05336109,-11.55189,-588332.9,0,0,0,-0.4446757,-10601.68
5.378,-0.0535972,-11.56675,-589089.9,0,0,0,-0.4466433,-10615.33
5.396,-0.05383331,-11.58656,-590098.8,0,0,0,-0.4486109,-10633.5
5.414,-0.05383331,-11.60934,-591259.1,0,0,0,-0.4486109,-10654.41
5.422,-0.05406942,-11.62277,-591942.8,0,0,0,-0.4505785,-10666.73
5.434,-0.05406942,-11.64771,-593212.8,0,0,0,-0.4505785,-10689.62
5.45,-0.05430553,-11.66896,-594295.2,0,0,0,-0.4525461,-10709.12
5.474,-0.05454164,-11.69239,-595488.4,0,0,0,-0.4545137,-10730.63
5.488,-0.05477776,-11.71083,-596427.4,0,0,0,-0.4564813,-10747.55
5.504,-0.05477776,-11.73613,-597716.1,0,0,0,-0.4564813,-10770.77
5.52,-0.05501387,-11.75179,-598514,0,0,0,-0.4584489,-10785.15
5.532,-0.05524998,-11.76666,-599271.1,0,0,0,-0.4604165,-10798.79
5.552,-0.05524998,-11.79023,-600471.6,0,0,0,-0.4604165,-10820.42
5.57,-0.05548609,-11.80303,-601123.6,0,0,0,-0.4623841,-10832.17
5.582,-0.0557222,-11.81879,-601926.3,0,0,0,-0.4643517,-10846.63
5.596,-0.0557222,-11.842,-603108.1,0,0,0,-0.4643517,-10867.93
5.612,-0.05595831,-11.86507,-604283.3,0,0,0,-0.4663192,-10889.11
5.628,-0.05619442,-11.8821,-605150.4,0,0,0,-0.4682868,-10904.73
5.644,-0.05619442,-11.90436,-606284.1,0,0,0,-0.4682868,-10925.16
5.656,-0.05643053,-11.92848,-607512.7,0,0,0,-0.4702544,-10947.3
5.676,-0.05666664,-11.93768,-607980.9,0,0,0,-0.472222,-10955.74
5.698,-0.05690275,-11.96169,-609204.1,0,0,0,-0.4741896,-10977.78
5.706,-0.05690275,-11.98579,-610431.3,0,0,0,-0.4741896,-10999.89
5.722,-0.05690275,-12.00586,-611453.6,0,0,0,-0.4741896,-11018.31
5.748,-0.05737497,-12.01481,-611909.2,0,0,0,-0.4781248,-11026.53
5.768,-0.05737497,-12.03703,-613040.9,0,0,0,-0.4781248,-11046.92
5.784,-0.05761109,-12.05406,-613908.2,0,0,0,-0.4800924,-11062.55
5.798,-0.0578472,-12.07147,-614794.8,0,0,0,-0.48206,-11078.52
5.81,-0.0578472,-12.09514,-616000.6,0,0,0,-0.48206,-11100.25
5.82,-0.05808331,-12.10995,-616754.6,0,0,0,-0.4840276,-11113.84
5.836,-0.05808331,-12.13306,-617931.6,0,0,0,-0.4840276,-11135.05
5.852,-0.05831942,-12.14972,-618780.3,0,0,0,-0.4859952,-11150.34
5.876,-0.05855553,-12.16914,-619769.1,0,0,0,-0.4879628,-11168.16
5.896,-0.05879164,-12.1902,-620841.6,0,0,0,-0.4899304,-11187.49
5.91,-0.05902775,-12.21613,-622162.4,0,0,0,-0.4918979,-11211.29
5.922,-0.05902775,-12.2449,-623627.4,0,0,0,-0.4918979,-11237.69
5.934,-0.05926386,-12.26737,-624771.8,0,0,0,-0.4938655,-11258.31
5.97,-0.05949998,-12.28575,-625707.9,0,0,0,-0.4958331,-11275.18
5.994,-0.05973608,-12.30945,-626914.9,0,0,0,-0.4978007,-11296.93
6.006,-0.05973608,-12.33564,-628249.2,0,0,0,-0.4978007,-11320.97
6.014,-0.05997219,-12.35693,-629333.4,0,0,0,-0.4997683,-11340.51
6.03,-0.05997219,-12.38075,-630546.6,0,0,0,-0.4997683,-11362.37
6.058,-0.06044442,-12.39022,-631028.8,0,0,0,-0.5037035,-11371.06
6.088,-0.06068053,-12.4054,-631801.7,0,0,0,-0.5056711,-11384.99
6.1,-0.06068053,-12.43208,-633160.7,0,0,0,-0.5056711,-11409.47
6.112,-0.06091664,-12.45717,-634438.4,0,0,0,-0.5076387,-11432.5
6.126,-0.06091664,-12.48066,-635634.7,0,0,0,-0.5076387,-11454.06
6.14,-0.06115275,-12.49697,-636465.6,0,0,0,-0.5096063,-11469.03
6.168,-0.06138886,-12.51629,-637449.7,0,0,0,-0.5115739,-11486.76
6.184,-0.06162497,-12.53527,-638416,0,0,0,-0.5135415,-11504.17
6.2,-0.06186108,-12.55836,-639592.2,0,0,0,-0.515509,-11525.37
6.212,-0.06186108,-12.58314,-640854.3,0,0,0,-0.515509,-11548.11
6.22,-0.0620972,-12.60463,-641948.3,0,0,0,-0.5174766,-11567.83
6.232,-0.0620972,-12.63018,-643249.7,0,0,0,-0.5174766,-11591.28
6.266,-0.06256942,-12.63001,-643241.4,0,0,0,-0.5214118,-11591.13
6.278,-0.06256942,-12.65591,-644560.3,0,0,0,-0.5214118,-11614.89
6.288,-0.06280552,-12.67141,-645349.5,0,0,0,-0.5233794,-11629.12
6.306,-0.06280552,-12.69509,-646555.4,0,0,0,-0.5233794,-11650.85
6.314,-0.06304164,-12.71038,-647334.3,0,0,0,-0.525347,-11664.88
6.326,-0.06304164,-12.73839,-648761.1,0,0,0,-0.525347,-11690.59
6.34,-0.06327775,-12.75248,-649478.3,0,0,0,-0.5273145,-11703.52
6.362,-0.06351386,-12.76704,-650220.2,0,0,0,-0.5292822,-11716.88
6.372,-0.06374998,-12.78927,-651352.3,0,0,0,-0.5312498,-11737.29
6.382,-0.06398609,-12.80945,-652380.1,0,0,0,-0.5332174,-11755.81
6.396,-0.06398609,-12.83339,-653599.2,0,0,0,-0.5332174,-11777.77
6.402,-0.0642222,-12.84869,-654378.5,0,0,0,-0.535185,-11791.82
6.41,-0.0642222,-12.8747,-655702.9,0,0,0,-0.535185,-11815.68
6.416,-0.0644583,-12.89527,-656750.9,0,0,0,-0.5371525,-11834.57
6.426,-0.0644583,-12.92015,-658017.9,0,0,0,-0.5371525,-11857.4
6.448,-0.06493053,-12.92074,-658048,0,0,0,-0.5410877,-11857.94
6.466,-0.06493053,-12.94519,-659293.1,0,0,0,-0.5410877,-11880.38
6.484,-0.06516664,-12.96773,-660441,0,0,0,-0.5430554,-11901.06
6.502,-0.06540275,-12.98228,-661182.3,0,0,0,-0.5450229,-11914.42
6.518,-0.06540275,-13.00625,-662403.1,0,0,0,-0.5450229,-11936.42
6.532,-0.06563886,-13.02115,-663161.6,0,0,0,-0.5469905,-11950.09
6.572,-0.06587497,-13.04226,-664236.8,0,0,0,-0.5489581,-11969.46
6.588,-0.06587497,-13.06596,-665443.9,0,0,0,-0.5489581,-11991.21
6.604,-0.06611108,-13.08283,-666302.9,0,0,0,-0.5509257,-12006.69
6.62,-0.06634719,-13.10338,-667349.8,0,0,0,-0.5528933,-12025.56
6.646,-0.06658331,-13.1167,-668027.9,0,0,0,-0.5548609,-12037.78
6.66,-0.06658331,-13.0934,-666841.5,0,0,0,-0.5548609,-12016.4
6.678,-0.06681942,-13.11356,-667868.1,0,0,0,-0.5568284,-12034.9
6.686,-0.06681942,-13.1353,-668975.5,0,0,0,-0.5568284,-12054.85
6.698,-0.06705553,-13.15917,-670191.3,0,0,0,-0.5587961,-12076.76
6.71,-0.06705553,-13.18297,-671403.3,0,0,0,-0.5587961,-12098.6
6.722,-0.06705553,-13.2074,-672647.3,0,0,0,-0.5587961,-12121.02
6.732,-0.06729164,-13.22321,-673452.6,0,0,0,-0.5607637,-12135.53
6.772,-0.06776386,-13.23846,-674229.3,0,0,0,-0.5646988,-12149.53
6.79,-0.06776386,-13.26198,-675427.3,0,0,0,-0.5646988,-12171.11
6.798,-0.06799997,-13.2836,-676528,0,0,0,-0.5666664,-12190.95
6.806,-0.06799997,-13.30666,-677702.5,0,0,0,-0.5666664,-12212.11
6.822,-0.06823608,-13.32652,-678713.9,0,0,0,-0.568634,-12230.34
6.846,-0.06823608,-13.34923,-679870.9,0,0,0,-0.568634,-12251.19
6.872,-0.0687083,-13.34427,-679617.9,0,0,0,-0.5725692,-12246.63
6.894,-0.0687083,-13.37237,-681049.4,0,0,0,-0.5725692,-12272.42
6.902,-0.06894442,-13.39585,-682245.2,0,0,0,-0.5745368,-12293.97
6.916,-0.06894442,-13.42103,-683527.5,0,0,0,-0.5745368,-12317.08
6.932,-0.06918052,-13.43497,-684237.6,0,0,0,-0.5765043,-12329.87
6.944,-0.06941664,-13.44807,-684904.4,0,0,0,-0.578472,-12341.89
6.968,-0.06965275,-13.46507,-685770.3,0,0,0,-0.5804396,-12357.49
6.982,-0.06965275,-13.48827,-686951.9,0,0,0,-0.5804396,-12378.79
6.994,-0.06988886,-13.5114,-688130.1,0,0,0,-0.5824072,-12400.02
7.008,-0.06988886,-13.53378,-689269.9,0,0,0,-0.5824072,-12420.56
7.02,-0.07012497,-13.55563,-690382.8,0,0,0,-0.5843747,-12440.61
7.038,-0.07036108,-13.56625,-690923.2,0,0,0,-0.5863424,-12450.35
7.062,-0.0705972,-13.58339,-691796.4,0,0,0,-0.58831,-12466.08
7.084,-0.0708333,-13.60735,-693016.7,0,0,0,-0.5902776,-12488.07
7.098,-0.0708333,-13.62918,-694128.5,0,0,0,-0.5902776,-12508.11
7.108,-0.07106941,-13.64605,-694987.6,0,0,0,-0.5922451,-12523.59
7.12,-0.07106941,-13.67014,-696214.5,0,0,0,-0.5922451,-12545.7
7.154,-0.07154164,-13.67613,-696519.5,0,0,0,-0.5961803,-12551.19
7.174,-0.07154164,-13.69992,-697731.3,0,0,0,-0.5961803,-12573.03
7.186,-0.07177775,-13.71831,-698667.6,0,0,0,-0.5981479,-12589.9
7.198,-0.07201386,-13.74577,-700066.2,0,0,0,-0.6001155,-12615.1
7.21,-0.07201386,-13.77416,-701512.1,0,0,0,-0.6001155,-12641.16
7.222,-0.07224997,-13.78669,-702150.6,0,0,0,-0.6020831,-12652.66
7.252,-0.07248608,-13.80901,-703287.1,0,0,0,-0.6040506,-12673.14
7.266,-0.07272219,-13.83261,-704489,0,0,0,-0.6060182,-12694.8
7.28,-0.07272219,-13.85549,-705654.3,0,0,0,-0.6060182,-12715.8
7.298,-0.0729583,-13.87528,-706662.1,0,0,0,-0.6079859,-12733.96
7.314,-0.07319441,-13.89422,-707626.8,0,0,0,-0.6099535,-12751.34
7.336,-0.07343053,-13.9059,-708221.6,0,0,0,-0.6119211,-12762.06
7.36,-0.07366664,-13.92414,-709150.6,0,0,0,-0.6138886,-12778.8
7.37,-0.07366664,-13.9484,-710386.3,0,0,0,-0.6138886,-12801.07
7.382,-0.07366664,-13.97547,-711764.6,0,0,0,-0.6138886,-12825.91
7.39,-0.07390274,-13.99269,-712642,0,0,0,-0.6158562,-12841.72
7.404,-0.07390274,-14.0128,-713666,0,0,0,-0.6158562,-12860.17
7.416,-0.07413886,-14.02864,-714472.9,0,0,0,-0.6178238,-12874.71
7.43,-0.07437497,-14.04197,-715151.5,0,0,0,-0.6197914,-12886.94
7.458,-0.07461108,-14.05385,-715756.8,0,0,0,-0.621759,-12897.85
7.468,-0.07461108,-14.07917,-717046.3,0,0,0,-0.621759,-12921.08
7.474,-0.07484719,-14.09365,-717783.7,0,0,0,-0.6237266,-12934.37
7.492,-0.07484719,-14.11568,-718905.5,0,0,0,-0.6237266,-12954.59
7.506,-0.0750833,-14.13111,-719691.6,0,0,0,-0.6256942,-12968.75
7.52,-0.07531942,-14.14252,-720272.8,0,0,0,-0.6276618,-12979.22
7.55,-0.07555552,-14.15313,-720813,0,0,0,-0.6296294,-12988.96
7.562,-0.07555552,-14.18189,-722277.6,0,0,0,-0.6296294,-13015.35
7.576,-0.07579163,-14.2046,-723434.4,0,0,0,-0.6315969,-13036.2
7.592,-0.07602775,-14.21753,-724092.7,0,0,0,-0.6335645,-13048.06
7.618,-0.07626386,-14.23122,-724789.9,0,0,0,-0.6355321,-13060.62
7.638,-0.07626386,-14.25481,-725991.8,0,0,0,-0.6355321,-13082.28
7.65,-0.07649997,-14.27521,-727030.6,0,0,0,-0.6374997,-13101
7.664,-0.07649997,-14.29983,-728284.4,0,0,0,-0.6374997,-13123.59
7.678,-0.07673609,-14.31762,-729190.4,0,0,0,-0.6394674,-13139.92
7.696,-0.07697219,-14.32932,-729786.3,0,0,0,-0.6414349,-13150.66
7.73,-0.0772083,-14.351,-730890.3,0,0,0,-0.6434025,-13170.55
7.746,-0.07744441,-14.36978,-731846.8,0,0,0,-0.6453701,-13187.79
7.768,-0.07744441,-14.39073,-732913.8,0,0,0,-0.6453701,-13207.01
7.776,-0.07768052,-14.41533,-734166.6,0,0,0,-0.6473377,-13229.59
7.798,-0.07791664,-14.42237,-734525.2,0,0,0,-0.6493053,-13236.05
7.822,-0.07815275,-14.4214,-734476,0,0,0,-0.651273,-13235.16
7.832,-0.07815275,-14.44792,-735826.6,0,0,0,-0.651273,-13259.5
7.842,-0.07815275,-14.4729,-737098.6,0,0,0,-0.651273,-13282.42
7.862,-0.07838886,-14.48918,-737928.1,0,0,0,-0.6532405,-13297.37
7.878,-0.07862496,-14.51012,-738994.1,0,0,0,-0.655208,-13316.58
7.894,-0.07886108,-14.53114,-740064.9,0,0,0,-0.6571757,-13335.88
7.918,-0.07909719,-14.55056,-741054.1,0,0,0,-0.6591433,-13353.7
7.93,-0.07909719,-14.57581,-742339.8,0,0,0,-0.6591433,-13376.87
7.942,-0.0793333,-14.59659,-743398.4,0,0,0,-0.6611109,-13395.94
7.962,-0.0793333,-14.61813,-744495.4,0,0,0,-0.6611109,-13415.71
7.976,-0.07956942,-14.63437,-745322.5,0,0,0,-0.6630785,-13430.62
8.002,-0.07980552,-14.65688,-746468.9,0,0,0,-0.665046,-13451.28
8.026,-0.08004164,-14.67457,-747369.8,0,0,0,-0.6670136,-13467.51
8.038,-0.08027774,-14.69071,-748191.8,0,0,0,-0.6689812,-13482.32
8.06,-0.08051386,-14.7126,-749306.5,0,0,0,-0.6709488,-13502.41
8.078,-0.08051386,-14.73389,-750390.8,0,0,0,-0.6709488,-13521.95
8.086,-0.08074997,-14.74744,-751081.1,0,0,0,-0.6729164,-13534.38
8.108,-0.08074997,-14.76983,-752221.3,0,0,0,-0.6729164,-13554.93
8.116,-0.08098608,-14.78273,-752878.3,0,0,0,-0.674884,-13566.77
8.13,-0.08098608,-14.80519,-754022.1,0,0,0,-0.674884,-13587.38
8.148,-0.08122219,-14.81793,-754671,0,0,0,-0.6768516,-13599.08
8.164,-0.0814583,-14.83634,-755608.6,0,0,0,-0.6788192,-13615.97
8.18,-0.08169441,-14.85221,-756417.1,0,0,0,-0.6807867,-13630.54
8.21,-0.08193052,-14.87224,-757437,0,0,0,-0.6827543,-13648.92
8.218,-0.08193052,-14.89328,-758508.8,0,0,0,-0.6827543,-13668.23
8.228,-0.08216663,-14.91611,-759671.5,0,0,0,-0.6847219,-13689.18
8.248,-0.08216663,-14.93813,-760792.6,0,0,0,-0.6847219,-13709.38
8.272,-0.08240275,-14.94984,-761389.1,0,0,0,-0.6866896,-13720.14
8.282,-0.08263885,-14.9628,-762049,0,0,0,-0.6886571,-13732.03
8.298,-0.08287497,-14.97924,-762886.4,0,0,0,-0.6906247,-13747.12
8.316,-0.08287497,-15.00229,-764060.3,0,0,0,-0.6906247,-13768.27
8.33,-0.08311108,-15.01836,-764878.8,0,0,0,-0.6925923,-13783.02
8.344,-0.08334719,-15.04071,-766017,0,0,0,-0.6945599,-13803.53
8.366,-0.0835833,-15.0618,-767091,0,0,0,-0.6965275,-13822.88
8.386,-0.0835833,-15.08553,-768299.8,0,0,0,-0.6965275,-13844.66
8.396,-0.08381941,-15.10406,-769243.4,0,0,0,-0.6984951,-13861.67
8.414,-0.08405552,-15.12426,-770272.4,0,0,0,-0.7004626,-13880.21
8.434,-0.08405552,-15.14513,-771335.3,0,0,0,-0.7004626,-13899.36
8.45,-0.08429163,-15.16325,-772258.1,0,0,0,-0.7024302,-13915.99
8.478,-0.08452775,-15.1816,-773192.6,0,0,0,-0.7043979,-13932.83
8.488,-0.08476386,-15.19577,-773914.4,0,0,0,-0.7063655,-13945.84
8.508,-0.08476386,-15.21928,-775111.6,0,0,0,-0.7063655,-13967.41
8.52,-0.08499997,-15.2338,-775851.1,0,0,0,-0.708333,-13980.74
8.532,-0.08523608,-15.25356,-776857.4,0,0,0,-0.7103007,-13998.87
8.55,-0.08523608,-15.2769,-778045.9,0,0,0,-0.7103007,-14020.29
8.56,-0.08547218,-15.29383,-778908.3,0,0,0,-0.7122682,-14035.83
8.576,-0.0857083,-15.31203,-779835.4,0,0,0,-0.7142358,-14052.53
8.608,-0.08594441,-15.32811,-780654,0,0,0,-0.7162035,-14067.29
8.62,-0.08618053,-15.34656,-781593.8,0,0,0,-0.7181711,-14084.22
8.636,-0.08618053,-15.36724,-782647.3,0,0,0,-0.7181711,-14103.21
8.652,-0.08641663,-15.39174,-783894.7,0,0,0,-0.7201386,-14125.68
8.668,-0.08665274,-15.41231,-784942.4,0,0,0,-0.7221062,-14144.56
8.69,-0.08688885,-15.42431,-785553.6,0,0,0,-0.7240738,-14155.58
8.708,-0.08688885,-15.44725,-786721.8,0,0,0,-0.7240738,-14176.63
8.724,-0.08712496,-15.47047,-787904.6,0,0,0,-0.7260414,-14197.94
8.74,-0.08736108,-15.48968,-788883,0,0,0,-0.728009,-14215.57
8.766,-0.08759719,-15.5078,-789805.9,0,0,0,-0.7299766,-14232.2
8.798,-0.0878333,-15.5291,-790890.6,0,0,0,-0.7319442,-14251.75
8.814,-0.08806941,-15.55339,-792127.8,0,0,0,-0.7339118,-14274.04
8.83,-0.08806941,-15.57815,-793388.5,0,0,0,-0.7339118,-14296.76
8.85,-0.08830551,-15.60166,-794585.9,0,0,0,-0.7358793,-14318.34
8.864,-0.08854163,-15.61862,-795449.6,0,0,0,-0.7378469,-14333.9
8.886,-0.08877774,-15.63625,-796347.5,0,0,0,-0.7398145,-14350.08
8.902,-0.08877774,-15.65959,-797536.4,0,0,0,-0.7398145,-14371.5
8.916,-0.08901386,-15.67752,-798449.7,0,0,0,-0.7417821,-14387.96
8.932,-0.08924997,-15.69279,-799227.2,0,0,0,-0.7437497,-14401.97
8.948,-0.08924997,-15.71503,-800359.9,0,0,0,-0.7437497,-14422.38
8.964,-0.08948608,-15.73178,-801213.2,0,0,0,-0.7457173,-14437.76
8.976,-0.08972218,-15.74599,-801936.8,0,0,0,-0.7476848,-14450.8
8.998,-0.08995829,-15.75875,-802586.6,0,0,0,-0.7496524,-14462.51
9.028,-0.09019441,-15.78117,-803728.5,0,0,0,-0.7516201,-14483.08
9.038,-0.09019441,-15.80321,-804850.8,0,0,0,-0.7516201,-14503.31
9.054,-0.09043052,-15.8225,-805833.3,0,0,0,-0.7535877,-14521.01
9.068,-0.09066664,-15.83873,-806659.9,0,0,0,-0.7555553,-14535.91
9.086,-0.09066664,-15.86075,-807781.2,0,0,0,-0.7555553,-14556.11
9.112,-0.09090274,-15.87411,-808461.8,0,0,0,-0.7575228,-14568.38
9.124,-0.09113885,-15.888,-809169.2,0,0,0,-0.7594904,-14581.13
9.136,-0.09137496,-15.90928,-810252.8,0,0,0,-0.761458,-14600.65
9.15,-0.09137496,-15.93097,-811357.4,0,0,0,-0.761458,-14620.56
9.174,-0.09161107,-15.94689,-812168.5,0,0,0,-0.7634256,-14635.17
9.184,-0.09184719,-15.96203,-812939.4,0,0,0,-0.7653932,-14649.06
9.208,-0.09208329,-15.98002,-813855.9,0,0,0,-0.7673607,-14665.58
9.226,-0.09208329,-16.0024,-814995.6,0,0,0,-0.7673607,-14686.12
9.24,-0.09231941,-16.02314,-816051.9,0,0,0,-0.7693284,-14705.15
9.256,-0.09255552,-16.03835,-816826.4,0,0,0,-0.771296,-14719.11
9.28,-0.09279162,-16.05995,-817926.4,0,0,0,-0.7732635,-14738.93
9.304,-0.09302774,-16.08195,-819047.1,0,0,0,-0.7752311,-14759.12
9.316,-0.09302774,-16.10971,-820460.6,0,0,0,-0.7752311,-14784.6
9.326,-0.09326385,-16.1326,-821626.6,0,0,0,-0.7771988,-14805.61
9.352,-0.09349996,-16.15162,-822595.2,0,0,0,-0.7791663,-14823.06
9.374,-0.09373607,-16.17067,-823565.4,0,0,0,-0.7811339,-14840.54
9.4,-0.09397218,-16.18822,-824459.1,0,0,0,-0.7831016,-14856.65
9.414,-0.09397218,-16.21271,-825706.5,0,0,0,-0.7831016,-14879.13
9.432,-0.09420829,-16.2328,-826729.9,0,0,0,-0.7850691,-14897.57
9.47,-0.09468052,-16.24416,-827308.5,0,0,0,-0.7890043,-14907.99
9.484,-0.09468052,-16.26651,-828446.6,0,0,0,-0.7890043,-14928.5
9.496,-0.09491662,-16.29366,-829829.2,0,0,0,-0.7909719,-14953.42
9.51,-0.09491662,-16.31864,-831101.4,0,0,0,-0.7909719,-14976.34
9.526,-0.09515274,-16.34013,-832195.9,0,0,0,-0.7929395,-14996.07
9.542,-0.09538885,-16.35758,-833084.6,0,0,0,-0.7949071,-15012.08
9.586,-0.09562496,-16.36782,-833606.2,0,0,0,-0.7968747,-15021.48
9.596,-0.09586107,-16.39195,-834835.1,0,0,0,-0.7988423,-15043.62
9.606,-0.09586107,-16.41364,-835939.9,0,0,0,-0.7988423,-15063.53
9.636,-0.09633329,-16.42642,-836590.5,0,0,0,-0.8027774,-15075.25
9.648,-0.09633329,-16.4485,-837715.3,0,0,0,-0.8027774,-15095.52
9.676,-0.0965694,-16.46665,-838639.9,0,0,0,-0.804745,-15112.18
9.686,-0.09680552,-16.4932,-839992.1,0,0,0,-0.8067126,-15136.55
9.694,-0.09680552,-16.51482,-841093.1,0,0,0,-0.8067126,-15156.39
9.704,-0.09680552,-16.53598,-842170.6,0,0,0,-0.8067126,-15175.81
9.732,-0.09727774,-16.54457,-842607.9,0,0,0,-0.8106478,-15183.69
9.762,-0.09751385,-16.56694,-843747.5,0,0,0,-0.8126154,-15204.22
9.772,-0.09751385,-16.59219,-845033.1,0,0,0,-0.8126154,-15227.39
9.786,-0.09774995,-16.61713,-846303.5,0,0,0,-0.8145829,-15250.28
9.816,-0.09798607,-16.6345,-847188.3,0,0,0,-0.8165506,-15266.22
9.838,-0.09822218,-16.64952,-847953.1,0,0,0,-0.8185182,-15280.01
9.852,-0.09845829,-16.6702,-849006.1,0,0,0,-0.8204858,-15298.98
9.864,-0.09845829,-16.69416,-850226.5,0,0,0,-0.8204858,-15320.97
9.876,-0.09869441,-16.71171,-851120.4,0,0,0,-0.8224534,-15337.08
9.89,-0.09893051,-16.72331,-851711.1,0,0,0,-0.8244209,-15347.72
9.908,-0.09893051,-16.74948,-853043.8,0,0,0,-0.8244209,-15371.74
9.916,-0.09916662,-16.76486,-853827.4,0,0,0,-0.8263885,-15385.86
9.932,-0.09940273,-16.78029,-854613.1,0,0,0,-0.8283561,-15400.02
9.954,-0.09963885,-16.79921,-855576.6,0,0,0,-0.8303237,-15417.38
9.97,-0.09963885,-16.82444,-856861.6,0,0,0,-0.8303237,-15440.54
9.99,-0.09987496,-16.84077,-857693.6,0,0,0,-0.8322913,-15455.53
9.998,-0.1001111,-16.8472,-858020.9,0,0,0,-0.834259,-15461.43