File: raw-data/steel_1_Sp15_245L_sect-001_group-2-4_bendtest-steel.raw
#"Test Type","Manual"
#"Method Name:","C:\INSTRON\user\template\245L-Mod01.mtM"
#"Name:","4FtPerMin"
#"Operator ID:","Jaques"
#"Company:","BSU"
#"Lab name:",""
#"Test date:","2/2/15"
#"Temperature:",""
#"Humidity:",""
#"Note 1:",""
#"Note 2:",""
#"Note 3:",""
#"Geometry:","Circular"
#"Specimen",1
#"Specimen name:",""
#"Width:",6.350000,"mm"
#"Thickness:",1.524000,"mm"
#"Length:",12.000000,"mm"
#"Diameter:",5.000000,"um"
#"Inner diameter:",0.500000,"mm"
#"Outer diameter:",1.000000,"mm"
#"Wall thickness:",0.500000,"mm"
#"Area:",19.634954,"um*um"
#"Linear density:",1.000000,"den"
#"Sled weight:",9.806650,"N"
#"Loading span:",0.000000,"mm"
#"Support span:",1.000000,"mm"
#"Span ratio:","2"
#"Fixture type:","3-point"
#"Comment:",""
#"Included"
#"Time sec","Extension mm","Load N","Stress MPa","Cycle Count ","Total Cycle Count ","Repetitions Count ","Strain [Exten.] %","Tenacity gf/tex"
0,0,-5.583295,-284354.9,0,0,0,0,-5124.039
0.032,0,-5.616856,-286064.1,0,0,0,0,-5154.839
0.062,-0.000236111,-5.618447,-286145.2,0,0,0,-0.001967592,-5156.3
0.126,-0.000236111,-5.636805,-287080.1,0,0,0,-0.001967592,-5173.147
0.138,-0.000236111,-5.671161,-288829.9,0,0,0,-0.001967592,-5204.678
0.154,-0.000472222,-5.704967,-290551.6,0,0,0,-0.003935183,-5235.703
0.17,-0.000472222,-5.739629,-292316.9,0,0,0,-0.003935183,-5267.514
0.192,-0.000472222,-5.773653,-294049.7,0,0,0,-0.003935183,-5298.739
0.212,-0.0007083331,-5.800105,-295396.9,0,0,0,-0.005902776,-5323.015
0.236,-0.000944444,-5.833882,-297117.2,0,0,0,-0.007870367,-5354.014
0.248,-0.000944444,-5.886434,-299793.6,0,0,0,-0.007870367,-5402.243
0.254,-0.000944444,-5.919107,-301457.7,0,0,0,-0.007870367,-5432.229
0.264,-0.001180555,-5.957379,-303406.8,0,0,0,-0.009837959,-5467.352
0.3,-0.001416666,-5.993821,-305262.8,0,0,0,-0.01180555,-5500.796
0.314,-0.001416666,-6.025623,-306882.4,0,0,0,-0.01180555,-5529.982
0.328,-0.001652777,-6.064299,-308852.3,0,0,0,-0.01377314,-5565.478
0.34,-0.001652777,-6.115951,-311482.8,0,0,0,-0.01377314,-5612.881
0.352,-0.001652777,-6.157223,-313584.8,0,0,0,-0.01377314,-5650.758
0.362,-0.001888888,-6.185364,-315018,0,0,0,-0.01574073,-5676.584
0.382,-0.001888888,-6.222217,-316894.9,0,0,0,-0.01574073,-5710.406
0.398,-0.002124999,-6.250886,-318355,0,0,0,-0.01770833,-5736.717
0.412,-0.002124999,-6.286678,-320177.9,0,0,0,-0.01770833,-5769.564
0.424,-0.002124999,-6.323538,-322055.1,0,0,0,-0.01770833,-5803.393
0.434,-0.00236111,-6.359993,-323911.8,0,0,0,-0.01967592,-5836.85
0.47,-0.002597221,-6.386222,-325247.6,0,0,0,-0.02164351,-5860.921
0.488,-0.002833332,-6.422787,-327109.9,0,0,0,-0.0236111,-5894.479
0.5,-0.002833332,-6.472065,-329619.6,0,0,0,-0.0236111,-5939.702
0.51,-0.003069443,-6.516468,-331881,0,0,0,-0.02557869,-5980.454
0.518,-0.003305554,-6.558517,-334022.5,0,0,0,-0.02754628,-6019.043
0.524,-0.003305554,-6.593964,-335827.8,0,0,0,-0.02754628,-6051.574
0.53,-0.003305554,-6.632577,-337794.4,0,0,0,-0.02754628,-6087.011
0.536,-0.003541665,-6.672178,-339811.3,0,0,0,-0.02951388,-6123.355
0.542,-0.003541665,-6.711872,-341832.8,0,0,0,-0.02951388,-6159.785
0.548,-0.003777776,-6.750661,-343808.3,0,0,0,-0.03148147,-6195.383
0.554,-0.003777776,-6.787771,-345698.3,0,0,0,-0.03148147,-6229.44
0.56,-0.003777776,-6.824282,-347557.8,0,0,0,-0.03148147,-6262.948
0.566,-0.004013887,-6.858108,-349280.6,0,0,0,-0.03344906,-6293.991
0.576,-0.004013887,-6.905047,-351671.2,0,0,0,-0.03344906,-6337.07
0.586,-0.004249998,-6.944757,-353693.6,0,0,0,-0.03541665,-6373.514
0.598,-0.004486109,-6.99098,-356047.7,0,0,0,-0.03738425,-6415.935
0.606,-0.00472222,-7.034987,-358288.9,0,0,0,-0.03935184,-6456.321
0.612,-0.00472222,-7.069263,-360034.6,0,0,0,-0.03935184,-6487.778
0.618,-0.00472222,-7.10113,-361657.6,0,0,0,-0.03935184,-6517.023
0.628,-0.004958331,-7.14958,-364125.2,0,0,0,-0.04131943,-6561.489
0.638,-0.005194443,-7.198686,-366626.1,0,0,0,-0.04328702,-6606.555
0.644,-0.005194443,-7.235283,-368490,0,0,0,-0.04328702,-6640.142
0.65,-0.005430553,-7.275456,-370535.9,0,0,0,-0.04525461,-6677.01
0.656,-0.005430553,-7.313763,-372486.9,0,0,0,-0.04525461,-6712.166
0.662,-0.005430553,-7.347837,-374222.3,0,0,0,-0.04525461,-6743.438
0.672,-0.005666665,-7.388465,-376291.4,0,0,0,-0.0472222,-6780.724
0.684,-0.005902775,-7.427444,-378276.6,0,0,0,-0.04918979,-6816.496
0.696,-0.006138886,-7.469767,-380432.1,0,0,0,-0.05115739,-6855.338
0.708,-0.006138886,-7.512723,-382619.8,0,0,0,-0.05115739,-6894.761
0.72,-0.006374997,-7.554661,-384755.7,0,0,0,-0.05312498,-6933.249
0.73,-0.006611108,-7.592898,-386703.1,0,0,0,-0.05509257,-6968.341
0.742,-0.006611108,-7.642922,-389250.8,0,0,0,-0.05509257,-7014.251
0.754,-0.00684722,-7.684511,-391368.9,0,0,0,-0.05706016,-7052.418
0.764,-0.00708333,-7.729409,-393655.6,0,0,0,-0.05902775,-7093.624
0.776,-0.00708333,-7.775142,-395984.7,0,0,0,-0.05902775,-7135.594
0.788,-0.007319441,-7.808007,-397658.5,0,0,0,-0.06099534,-7165.756
0.8,-0.007555552,-7.840966,-399337.1,0,0,0,-0.06296293,-7196.004
0.812,-0.007555552,-7.879663,-401308,0,0,0,-0.06296293,-7231.519
0.824,-0.007791664,-7.916362,-403177,0,0,0,-0.06493053,-7265.198
0.836,-0.008027775,-7.962186,-405510.8,0,0,0,-0.06689812,-7307.253
0.848,-0.008027775,-8.015467,-408224.4,0,0,0,-0.06689812,-7356.151
0.858,-0.008263885,-8.054201,-410197.1,0,0,0,-0.06886571,-7391.699
0.87,-0.008263885,-8.089544,-411997.1,0,0,0,-0.06886571,-7424.135
0.884,-0.008499997,-8.120931,-413595.6,0,0,0,-0.0708333,-7452.94
0.896,-0.008736108,-8.153823,-415270.8,0,0,0,-0.0728009,-7483.127
0.908,-0.008736108,-8.194967,-417366.3,0,0,0,-0.0728009,-7520.887
0.918,-0.008972219,-8.229073,-419103.3,0,0,0,-0.07476849,-7552.188
0.932,-0.00920833,-8.267258,-421048,0,0,0,-0.07673608,-7587.231
0.946,-0.00920833,-8.305651,-423003.3,0,0,0,-0.07673608,-7622.466
0.956,-0.00944444,-8.350034,-425263.8,0,0,0,-0.07870367,-7663.199
0.968,-0.00944444,-8.39841,-427727.5,0,0,0,-0.07870367,-7707.595
1,-0.009916663,-8.433556,-429517.5,0,0,0,-0.08263886,-7739.851
1.012,-0.009916663,-8.482775,-432024.2,0,0,0,-0.08263886,-7785.021
1.022,-0.01015277,-8.531013,-434480.9,0,0,0,-0.08460645,-7829.291
1.034,-0.01015277,-8.580601,-437006.4,0,0,0,-0.08460645,-7874.8
1.05,-0.01038889,-8.61284,-438648.3,0,0,0,-0.08657404,-7904.387
1.066,-0.010625,-8.645176,-440295.2,0,0,0,-0.08854163,-7934.063
1.078,-0.010625,-8.684917,-442319.2,0,0,0,-0.08854163,-7970.536
1.09,-0.01086111,-8.721524,-444183.6,0,0,0,-0.09050922,-8004.131
1.108,-0.01086111,-8.761142,-446201.3,0,0,0,-0.09050922,-8040.491
1.118,-0.01109722,-8.792081,-447777,0,0,0,-0.09247681,-8068.885
1.13,-0.01109722,-8.83274,-449847.8,0,0,0,-0.09247681,-8106.199
1.14,-0.01133333,-8.865393,-451510.8,0,0,0,-0.09444441,-8136.167
1.154,-0.01133333,-8.901625,-453356,0,0,0,-0.09444441,-8169.418
1.172,-0.01156944,-8.934513,-455031,0,0,0,-0.096412,-8199.601
1.182,-0.01180555,-8.969779,-456827.1,0,0,0,-0.09837959,-8231.966
1.194,-0.01180555,-9.020574,-459414.1,0,0,0,-0.09837959,-8278.583
1.216,-0.01204166,-9.052835,-461057.1,0,0,0,-0.1003472,-8308.19
1.228,-0.01227777,-9.084932,-462691.8,0,0,0,-0.1023148,-8337.646
1.24,-0.01227777,-9.128015,-464886,0,0,0,-0.1023148,-8377.186
1.252,-0.01251388,-9.161443,-466588.5,0,0,0,-0.1042824,-8407.865
1.264,-0.01251388,-9.20591,-468853.2,0,0,0,-0.1042824,-8448.675
1.274,-0.01274999,-9.244086,-470797.5,0,0,0,-0.10625,-8483.71
1.286,-0.01274999,-9.279363,-472594.1,0,0,0,-0.10625,-8516.085
1.298,-0.01298611,-9.317174,-474519.8,0,0,0,-0.1082175,-8550.786
1.31,-0.01298611,-9.359865,-476694,0,0,0,-0.1082175,-8589.966
1.332,-0.01322222,-9.394075,-478436.3,0,0,0,-0.1101851,-8621.361
1.344,-0.01345833,-9.42201,-479859,0,0,0,-0.1121527,-8646.999
1.356,-0.01345833,-9.467907,-482196.6,0,0,0,-0.1121527,-8689.121
1.368,-0.01345833,-9.508365,-484257.1,0,0,0,-0.1121527,-8726.25
1.378,-0.01369444,-9.537684,-485750.3,0,0,0,-0.1141203,-8753.158
1.39,-0.01369444,-9.574673,-487634.1,0,0,0,-0.1141203,-8787.104
1.402,-0.01393055,-9.604847,-489170.8,0,0,0,-0.1160879,-8814.797
1.416,-0.01416666,-9.644518,-491191.3,0,0,0,-0.1180555,-8851.204
1.428,-0.01416666,-9.68566,-493286.6,0,0,0,-0.1180555,-8888.962
1.44,-0.01440277,-9.71183,-494619.4,0,0,0,-0.1200231,-8912.979
1.462,-0.01440277,-9.749788,-496552.6,0,0,0,-0.1200231,-8947.815
1.472,-0.01463888,-9.785254,-498358.9,0,0,0,-0.1219907,-8980.363
1.484,-0.01463888,-9.837995,-501045,0,0,0,-0.1219907,-9028.767
1.496,-0.01487499,-9.88163,-503267.3,0,0,0,-0.1239583,-9068.813
1.51,-0.0151111,-9.917487,-505093.5,0,0,0,-0.1259259,-9101.721
1.524,-0.0151111,-9.954242,-506965.4,0,0,0,-0.1259259,-9135.452
1.534,-0.01534721,-9.986625,-508614.7,0,0,0,-0.1278935,-9165.171
1.546,-0.01534721,-10.02633,-510636.8,0,0,0,-0.1278935,-9201.611
1.558,-0.01558333,-10.06507,-512609.9,0,0,0,-0.1298611,-9237.165
1.57,-0.01558333,-10.10511,-514648.8,0,0,0,-0.1298611,-9273.906
1.582,-0.01581944,-10.14078,-516465.7,0,0,0,-0.1318286,-9306.646
1.6,-0.01581944,-10.1766,-518289.9,0,0,0,-0.1318286,-9339.519
1.624,-0.01605555,-10.20863,-519921.2,0,0,0,-0.1337962,-9368.913
1.636,-0.01629166,-10.25524,-522294.8,0,0,0,-0.1357638,-9411.687
1.642,-0.01629166,-10.28857,-523992.8,0,0,0,-0.1357638,-9442.284
1.65,-0.01652777,-10.32964,-526084.1,0,0,0,-0.1377314,-9479.968
1.662,-0.01652777,-10.37082,-528181.5,0,0,0,-0.1377314,-9517.764
1.674,-0.01676388,-10.40197,-529768,0,0,0,-0.139699,-9546.353
1.688,-0.01676388,-10.44342,-531879,0,0,0,-0.139699,-9584.393
1.698,-0.01699999,-10.47977,-533730.4,0,0,0,-0.1416666,-9617.755
1.71,-0.01699999,-10.51447,-535497.7,0,0,0,-0.1416666,-9649.601
1.73,-0.0172361,-10.54475,-537039.8,0,0,0,-0.1436342,-9677.388
1.742,-0.0172361,-10.58848,-539266.9,0,0,0,-0.1436342,-9717.521
1.752,-0.01747222,-10.63152,-541458.8,0,0,0,-0.1456018,-9757.018
1.764,-0.01747222,-10.6798,-543917.6,0,0,0,-0.1456018,-9801.325
1.776,-0.01770833,-10.71709,-545816.8,0,0,0,-0.1475694,-9835.548
1.788,-0.01794444,-10.74343,-547158.6,0,0,0,-0.149537,-9859.728
1.806,-0.01794444,-10.78139,-549091.5,0,0,0,-0.149537,-9894.559
1.816,-0.01818055,-10.81544,-550825.7,0,0,0,-0.1515046,-9925.809
1.828,-0.01818055,-10.86859,-553532.6,0,0,0,-0.1515046,-9974.586
1.84,-0.01841666,-10.91173,-555730.1,0,0,0,-0.1534722,-10014.18
1.858,-0.01841666,-10.94821,-557587.8,0,0,0,-0.1534722,-10047.66
1.868,-0.01865277,-10.97777,-559093.2,0,0,0,-0.1554397,-10074.79
1.884,-0.01888888,-11.01462,-560969.8,0,0,0,-0.1574073,-10108.6
1.898,-0.01888888,-11.05005,-562774.6,0,0,0,-0.1574073,-10141.13
1.91,-0.01912499,-11.09036,-564827.6,0,0,0,-0.1593749,-10178.12
1.922,-0.01912499,-11.12679,-566683,0,0,0,-0.1593749,-10211.56
1.934,-0.0193611,-11.15798,-568271.2,0,0,0,-0.1613425,-10240.17
1.946,-0.0193611,-11.20197,-570511.8,0,0,0,-0.1613425,-10280.55
1.958,-0.01959721,-11.24476,-572690.9,0,0,0,-0.1633101,-10319.82
1.974,-0.01959721,-11.2808,-574526.4,0,0,0,-0.1633101,-10352.89
1.988,-0.01983333,-11.31826,-576434,0,0,0,-0.1652777,-10387.27
2,-0.01983333,-11.35847,-578482.4,0,0,0,-0.1652777,-10424.18
2.014,-0.02006944,-11.3943,-580306.8,0,0,0,-0.1672453,-10457.05
2.026,-0.02030555,-11.43245,-582249.7,0,0,0,-0.1692129,-10492.07
2.038,-0.02030555,-11.47846,-584593.1,0,0,0,-0.1692129,-10534.29
2.05,-0.02030555,-11.52883,-587158.5,0,0,0,-0.1692129,-10580.52
2.062,-0.02054166,-11.55762,-588624.5,0,0,0,-0.1711805,-10606.94
2.082,-0.02077777,-11.58386,-589961,0,0,0,-0.1731481,-10631.02
2.094,-0.02077777,-11.61817,-591708.8,0,0,0,-0.1731481,-10662.52
2.108,-0.02101388,-11.65122,-593391.9,0,0,0,-0.1751157,-10692.85
2.126,-0.02124999,-11.68753,-595240.9,0,0,0,-0.1770833,-10726.16
2.138,-0.02124999,-11.73986,-597906.1,0,0,0,-0.1770833,-10774.19
2.15,-0.0214861,-11.79269,-600596.7,0,0,0,-0.1790509,-10822.68
2.162,-0.0214861,-11.82702,-602345.3,0,0,0,-0.1790509,-10854.18
2.174,-0.02172221,-11.85691,-603867.4,0,0,0,-0.1810184,-10881.61
2.188,-0.02172221,-11.89325,-605718.3,0,0,0,-0.1810184,-10914.97
2.204,-0.02195833,-11.92963,-607570.9,0,0,0,-0.1829861,-10948.35
2.216,-0.02219444,-11.96862,-609556.8,0,0,0,-0.1849536,-10984.14
2.228,-0.02219444,-12.00922,-611624.7,0,0,0,-0.1849536,-11021.4
2.242,-0.02243054,-12.04357,-613374,0,0,0,-0.1869212,-11052.92
2.256,-0.02243054,-12.07958,-615207.9,0,0,0,-0.1869212,-11085.97
2.266,-0.02266666,-12.1164,-617083.4,0,0,0,-0.1888888,-11119.76
2.278,-0.02266666,-12.16001,-619304.2,0,0,0,-0.1888888,-11159.78
2.29,-0.02290277,-12.18719,-620688.3,0,0,0,-0.1908564,-11184.72
2.306,-0.02290277,-12.22313,-622519,0,0,0,-0.1908564,-11217.71
2.316,-0.02313888,-12.2504,-623907.8,0,0,0,-0.192824,-11242.74
2.33,-0.02313888,-12.28455,-625646.8,0,0,0,-0.192824,-11274.08
2.346,-0.02337499,-12.32103,-627504.7,0,0,0,-0.1947916,-11307.55
2.358,-0.02337499,-12.37173,-630087,0,0,0,-0.1947916,-11354.09
2.368,-0.0236111,-12.41464,-632272.4,0,0,0,-0.1967592,-11393.47
2.384,-0.02384721,-12.44987,-634066.6,0,0,0,-0.1987268,-11425.8
2.396,-0.02384721,-12.48468,-635839.8,0,0,0,-0.1987268,-11457.75
2.406,-0.02408332,-12.513,-637281.8,0,0,0,-0.2006944,-11483.74
2.424,-0.02408332,-12.5504,-639186.5,0,0,0,-0.2006944,-11518.06
2.436,-0.02431944,-12.59328,-641370.4,0,0,0,-0.202662,-11557.41
2.448,-0.02431944,-12.64517,-644013.3,0,0,0,-0.202662,-11605.04
2.458,-0.02455555,-12.6752,-645542.5,0,0,0,-0.2046295,-11632.59
2.47,-0.02455555,-12.70726,-647175.6,0,0,0,-0.2046295,-11662.02
2.482,-0.02479165,-12.74521,-649108.1,0,0,0,-0.2065971,-11696.84
2.494,-0.02479165,-12.78322,-651044.1,0,0,0,-0.2065971,-11731.73
2.506,-0.02502777,-12.81328,-652574.9,0,0,0,-0.2085647,-11759.32
2.52,-0.02526388,-12.84622,-654252.7,0,0,0,-0.2105323,-11789.55
2.534,-0.02526388,-12.88672,-656315.4,0,0,0,-0.2105323,-11826.72
2.544,-0.02549999,-12.92635,-658333.4,0,0,0,-0.2124999,-11863.08
2.556,-0.02549999,-12.97195,-660656.2,0,0,0,-0.2124999,-11904.94
2.566,-0.0257361,-12.99984,-662076.3,0,0,0,-0.2144675,-11930.53
2.582,-0.0257361,-13.03858,-664049.5,0,0,0,-0.2144675,-11966.09
2.6,-0.02597221,-13.07933,-666124.7,0,0,0,-0.2164351,-12003.48
2.612,-0.02620832,-13.11149,-667762.6,0,0,0,-0.2184027,-12033
2.624,-0.02620832,-13.15489,-669973.3,0,0,0,-0.2184027,-12072.83
2.636,-0.02644443,-13.19292,-671910.1,0,0,0,-0.2203703,-12107.74
2.652,-0.02644443,-13.23113,-673856.1,0,0,0,-0.2203703,-12142.8
2.664,-0.02668055,-13.27427,-676053.3,0,0,0,-0.2223379,-12182.39
2.676,-0.02668055,-13.32434,-678603,0,0,0,-0.2223379,-12228.34
2.688,-0.02691665,-13.35785,-680309.9,0,0,0,-0.2243055,-12259.1
2.7,-0.02691665,-13.39129,-682012.9,0,0,0,-0.2243055,-12289.79
2.71,-0.02715277,-13.42288,-683621.5,0,0,0,-0.2262731,-12318.77
2.722,-0.02715277,-13.45666,-685342.3,0,0,0,-0.2262731,-12349.78
2.74,-0.02738888,-13.49596,-687343.5,0,0,0,-0.2282407,-12385.84
2.752,-0.02762499,-13.52646,-688896.8,0,0,0,-0.2302082,-12413.83
2.764,-0.02762499,-13.56868,-691047.3,0,0,0,-0.2302082,-12452.58
2.776,-0.0278611,-13.60782,-693040.4,0,0,0,-0.2321758,-12488.5
2.788,-0.0278611,-13.64273,-694818.7,0,0,0,-0.2321758,-12520.54
2.798,-0.02809721,-13.67323,-696371.7,0,0,0,-0.2341434,-12548.53
2.81,-0.02809721,-13.71416,-698456.5,0,0,0,-0.2341434,-12586.1
2.82,-0.02833332,-13.74681,-700119.3,0,0,0,-0.236111,-12616.06
2.832,-0.02833332,-13.78017,-701818.6,0,0,0,-0.236111,-12646.68
2.844,-0.02856943,-13.80969,-703321.6,0,0,0,-0.2380786,-12673.77
2.858,-0.02856943,-13.84686,-705214.6,0,0,0,-0.2380786,-12707.88
2.868,-0.02880554,-13.88434,-707123.5,0,0,0,-0.2400462,-12742.28
2.88,-0.02880554,-13.93765,-709838.7,0,0,0,-0.2400462,-12791.2
2.892,-0.02904166,-13.98798,-712402,0,0,0,-0.2420138,-12837.39
2.914,-0.02927776,-14.02029,-714047.4,0,0,0,-0.2439814,-12867.04
2.932,-0.02927776,-14.05538,-715834.6,0,0,0,-0.2439814,-12899.25
2.942,-0.02951388,-14.09242,-717721.2,0,0,0,-0.245949,-12933.24
2.954,-0.02951388,-14.13411,-719844.4,0,0,0,-0.245949,-12971.5
2.966,-0.02974999,-14.16694,-721516.1,0,0,0,-0.2479166,-13001.63
2.978,-0.02974999,-14.2129,-723856.9,0,0,0,-0.2479166,-13043.81
2.99,-0.0299861,-14.25632,-726068.2,0,0,0,-0.2498841,-13083.66
3.006,-0.0299861,-14.29297,-727934.8,0,0,0,-0.2498841,-13117.29
3.018,-0.03022221,-14.33655,-730154.6,0,0,0,-0.2518517,-13157.29
3.03,-0.03022221,-14.3818,-732459.1,0,0,0,-0.2518517,-13198.82
3.046,-0.03045832,-14.40879,-733833.8,0,0,0,-0.2538193,-13223.59
3.062,-0.03069443,-14.45022,-735943.5,0,0,0,-0.2557869,-13261.61
3.074,-0.03093054,-14.49791,-738372.4,0,0,0,-0.2577545,-13305.38
3.086,-0.03093054,-14.53949,-740490.1,0,0,0,-0.2577545,-13343.54
3.096,-0.03116666,-14.56609,-741844.9,0,0,0,-0.2597221,-13367.95
3.108,-0.03116666,-14.60823,-743991.3,0,0,0,-0.2597221,-13406.63
3.12,-0.03140276,-14.65145,-746192.5,0,0,0,-0.2616897,-13446.29
3.134,-0.03140276,-14.68691,-747998.3,0,0,0,-0.2616897,-13478.83
3.148,-0.03163887,-14.7192,-749642.7,0,0,0,-0.2636573,-13508.47
3.16,-0.03163887,-14.75989,-751715.1,0,0,0,-0.2636573,-13545.81
3.172,-0.03187499,-14.804,-753961.5,0,0,0,-0.2656249,-13586.29
3.188,-0.03187499,-14.8417,-755881.7,0,0,0,-0.2656249,-13620.89
3.2,-0.0321111,-14.87323,-757487.2,0,0,0,-0.2675925,-13649.82
3.212,-0.0321111,-14.91524,-759627,0,0,0,-0.2675925,-13688.38
3.222,-0.03234721,-14.94641,-761214.4,0,0,0,-0.2695601,-13716.99
3.234,-0.03234721,-14.98041,-762945.8,0,0,0,-0.2695601,-13748.19
3.248,-0.03258332,-15.01468,-764691.4,0,0,0,-0.2715277,-13779.64
3.268,-0.03281943,-15.04748,-766361.8,0,0,0,-0.2734953,-13809.74
3.282,-0.03281943,-15.08529,-768287.8,0,0,0,-0.2734953,-13844.45
3.294,-0.03305554,-15.1332,-770727.8,0,0,0,-0.2754628,-13888.42
3.306,-0.03305554,-15.17663,-772939.6,0,0,0,-0.2754628,-13928.27
3.322,-0.03329165,-15.21216,-774748.9,0,0,0,-0.2774304,-13960.88
3.334,-0.03329165,-15.25315,-776836.3,0,0,0,-0.2774304,-13998.49
3.346,-0.03352777,-15.29566,-779001.5,0,0,0,-0.2793981,-14037.51
3.362,-0.03352777,-15.32938,-780719.1,0,0,0,-0.2793981,-14068.46
3.374,-0.03376387,-15.35975,-782265.7,0,0,0,-0.2813656,-14096.33
3.386,-0.03399999,-15.40202,-784418.4,0,0,0,-0.2833332,-14135.12
3.398,-0.03399999,-15.44268,-786489.3,0,0,0,-0.2833332,-14172.44
3.41,-0.0342361,-15.48358,-788572.4,0,0,0,-0.2853008,-14209.97
3.422,-0.0342361,-15.52507,-790685.1,0,0,0,-0.2853008,-14248.04
3.434,-0.03447221,-15.54847,-791877,0,0,0,-0.2872684,-14269.52
3.454,-0.03447221,-15.58228,-793599.1,0,0,0,-0.2872684,-14300.55
3.466,-0.03470832,-15.61954,-795496.9,0,0,0,-0.289236,-14334.75
3.478,-0.03470832,-15.66004,-797559.1,0,0,0,-0.289236,-14371.91
3.49,-0.03494443,-15.70113,-799651.9,0,0,0,-0.2912036,-14409.63
3.502,-0.03494443,-15.74642,-801958.6,0,0,0,-0.2912036,-14451.19
3.514,-0.03518054,-15.78793,-804072.6,0,0,0,-0.2931712,-14489.29
3.528,-0.03518054,-15.82524,-805972.9,0,0,0,-0.2931712,-14523.53
3.546,-0.03541665,-15.85243,-807357.5,0,0,0,-0.2951388,-14548.48
3.558,-0.03565276,-15.88105,-808815.2,0,0,0,-0.2971064,-14574.75
3.57,-0.03565276,-15.92272,-810937.4,0,0,0,-0.2971064,-14612.99
3.584,-0.03588887,-15.94959,-812306.1,0,0,0,-0.299074,-14637.65
3.598,-0.03588887,-15.98463,-814090.8,0,0,0,-0.299074,-14669.81
3.608,-0.03612498,-16.02556,-816175.3,0,0,0,-0.3010415,-14707.37
3.62,-0.03612498,-16.07446,-818665.8,0,0,0,-0.3010415,-14752.25
3.63,-0.0363611,-16.10682,-820313.8,0,0,0,-0.3030091,-14781.95
3.642,-0.0363611,-16.14156,-822082.9,0,0,0,-0.3030091,-14813.83
3.652,-0.03659721,-16.17603,-823838.3,0,0,0,-0.3049767,-14845.46
3.664,-0.03659721,-16.22266,-826213.3,0,0,0,-0.3049767,-14888.26
3.674,-0.03683332,-16.259,-828063.9,0,0,0,-0.3069443,-14921.61
3.69,-0.03683332,-16.29764,-830032.1,0,0,0,-0.3069443,-14957.07
3.706,-0.03706943,-16.32712,-831533.4,0,0,0,-0.3089119,-14984.13
3.722,-0.03730554,-16.36335,-833378.3,0,0,0,-0.3108795,-15017.37
3.734,-0.03730554,-16.40743,-835623.5,0,0,0,-0.3108795,-15057.83
3.744,-0.03754165,-16.45475,-838033.4,0,0,0,-0.3128471,-15101.25
3.756,-0.03754165,-16.50703,-840696.3,0,0,0,-0.3128471,-15149.24
3.768,-0.03777776,-16.53356,-842047.3,0,0,0,-0.3148147,-15173.58
3.786,-0.03801387,-16.56902,-843853.3,0,0,0,-0.3167823,-15206.13
3.8,-0.03801387,-16.60454,-845662.1,0,0,0,-0.3167823,-15238.72
3.81,-0.03824999,-16.63378,-847151.6,0,0,0,-0.3187499,-15265.56
3.822,-0.03824999,-16.67417,-849208.6,0,0,0,-0.3187499,-15302.63
3.834,-0.0384861,-16.71495,-851285.3,0,0,0,-0.3207175,-15340.05
3.846,-0.0384861,-16.75213,-853178.8,0,0,0,-0.3207175,-15374.17
3.858,-0.0384861,-16.79025,-855120.3,0,0,0,-0.3207175,-15409.16
3.868,-0.03872221,-16.82081,-856676.9,0,0,0,-0.322685,-15437.21
3.884,-0.03895832,-16.85704,-858522,0,0,0,-0.3246527,-15470.46
3.9,-0.03895832,-16.89583,-860497.7,0,0,0,-0.3246527,-15506.06
3.914,-0.03919443,-16.9281,-862141.3,0,0,0,-0.3266203,-15535.68
3.928,-0.03919443,-16.96724,-864134.5,0,0,0,-0.3266203,-15571.59
3.94,-0.03943054,-17.01582,-866608.4,0,0,0,-0.3285878,-15616.17
3.952,-0.03943054,-17.06314,-869018.4,0,0,0,-0.3285878,-15659.6
3.962,-0.03966665,-17.09604,-870694.4,0,0,0,-0.3305554,-15689.8
3.974,-0.03966665,-17.12945,-872395.8,0,0,0,-0.3305554,-15720.46
4.004,-0.04013887,-17.16199,-874053.2,0,0,0,-0.3344906,-15750.33
4.016,-0.04013887,-17.20595,-876291.7,0,0,0,-0.3344906,-15790.66
4.028,-0.04037498,-17.26028,-879058.8,0,0,0,-0.3364582,-15840.53
4.04,-0.04037498,-17.30489,-881330.8,0,0,0,-0.3364582,-15881.47
4.052,-0.04061109,-17.34743,-883497.5,0,0,0,-0.3384258,-15920.51
4.064,-0.04061109,-17.39115,-885723.9,0,0,0,-0.3384258,-15960.63
4.078,-0.0408472,-17.42458,-887426.7,0,0,0,-0.3403934,-15991.32
4.094,-0.04108332,-17.46407,-889437.8,0,0,0,-0.342361,-16027.56
4.108,-0.04108332,-17.5019,-891364.6,0,0,0,-0.342361,-16062.28
4.118,-0.04131943,-17.53569,-893085.4,0,0,0,-0.3443286,-16093.29
4.13,-0.04131943,-17.58613,-895654.4,0,0,0,-0.3443286,-16139.58
4.14,-0.04155554,-17.62776,-897774.3,0,0,0,-0.3462962,-16177.78
4.152,-0.04155554,-17.66858,-899853.6,0,0,0,-0.3462962,-16215.25
4.166,-0.04179165,-17.69567,-901233.3,0,0,0,-0.3482637,-16240.11
4.184,-0.04179165,-17.73514,-903243.2,0,0,0,-0.3482637,-16276.33
4.194,-0.04202776,-17.76368,-904696.7,0,0,0,-0.3502313,-16302.52
4.206,-0.04202776,-17.80757,-906932.4,0,0,0,-0.3502313,-16342.81
4.22,-0.04226387,-17.84761,-908971.6,0,0,0,-0.3521989,-16379.55
4.234,-0.04226387,-17.88493,-910871.8,0,0,0,-0.3521989,-16413.79
4.246,-0.04249998,-17.92769,-913049.8,0,0,0,-0.3541665,-16453.04
4.26,-0.04249998,-17.96613,-915007.4,0,0,0,-0.3541665,-16488.32
4.276,-0.04273609,-17.99463,-916458.9,0,0,0,-0.3561341,-16514.47
4.29,-0.04297221,-18.03058,-918290,0,0,0,-0.3581017,-16547.47
4.304,-0.04297221,-18.06698,-920143.8,0,0,0,-0.3581017,-16580.88
4.314,-0.04320832,-18.09729,-921687.4,0,0,0,-0.3600693,-16608.69
4.326,-0.04320832,-18.14901,-924321.3,0,0,0,-0.3600693,-16656.15
4.34,-0.04344442,-18.18673,-926242.4,0,0,0,-0.3620369,-16690.77
4.354,-0.04344442,-18.23087,-928490.4,0,0,0,-0.3620369,-16731.28
4.366,-0.04368054,-18.28723,-931361,0,0,0,-0.3640045,-16783.01
4.38,-0.04391665,-18.31779,-932917.3,0,0,0,-0.3659721,-16811.05
4.404,-0.04415276,-18.35807,-934968.8,0,0,0,-0.3679397,-16848.02
4.416,-0.04415276,-18.41204,-937717.6,0,0,0,-0.3679397,-16897.55
4.428,-0.04438887,-18.44636,-939465.6,0,0,0,-0.3699073,-16929.05
4.444,-0.04438887,-18.48804,-941588.3,0,0,0,-0.3699073,-16967.3
4.454,-0.04462499,-18.52481,-943461.1,0,0,0,-0.3718749,-17001.05
4.466,-0.04462499,-18.56471,-945492.9,0,0,0,-0.3718749,-17037.66
4.476,-0.04486109,-18.59612,-947092.6,0,0,0,-0.3738424,-17066.49
4.488,-0.04486109,-18.63175,-948907.1,0,0,0,-0.3738424,-17099.19
4.5,-0.0450972,-18.66752,-950728.8,0,0,0,-0.37581,-17132.01
4.512,-0.0450972,-18.70516,-952646.1,0,0,0,-0.37581,-17166.56
4.522,-0.04533332,-18.73668,-954251.3,0,0,0,-0.3777776,-17195.49
4.534,-0.04533332,-18.76996,-955946.3,0,0,0,-0.3777776,-17226.03
4.546,-0.04556942,-18.80921,-957945.3,0,0,0,-0.3797452,-17262.05
4.558,-0.04556942,-18.84781,-959911.3,0,0,0,-0.3797452,-17297.48
4.574,-0.04580554,-18.88424,-961766.4,0,0,0,-0.3817128,-17330.91
4.592,-0.04604165,-18.92361,-963771.4,0,0,0,-0.3836804,-17367.04
4.604,-0.04604165,-18.96928,-966097.6,0,0,0,-0.3836804,-17408.96
4.616,-0.04627776,-19.01418,-968384.3,0,0,0,-0.385648,-17450.16
4.628,-0.04627776,-19.05208,-970314.7,0,0,0,-0.385648,-17484.95
4.638,-0.04651387,-19.08533,-972008.1,0,0,0,-0.3876156,-17515.46
4.65,-0.04651387,-19.12843,-974203,0,0,0,-0.3876156,-17555.01
4.66,-0.04674998,-19.15844,-975731.1,0,0,0,-0.3895831,-17582.55
4.672,-0.04674998,-19.19705,-977697.9,0,0,0,-0.3895831,-17617.99
4.684,-0.04698609,-19.23722,-979743.4,0,0,0,-0.3915508,-17654.85
4.698,-0.04698609,-19.27441,-981637.6,0,0,0,-0.3915508,-17688.99
4.716,-0.0472222,-19.30209,-983047.6,0,0,0,-0.3935184,-17714.39
4.728,-0.0472222,-19.34212,-985085.9,0,0,0,-0.3935184,-17751.12
4.738,-0.04745831,-19.38112,-987072.3,0,0,0,-0.3954859,-17786.92
4.75,-0.04745831,-19.42212,-989160.4,0,0,0,-0.3954859,-17824.54
4.762,-0.04769443,-19.46414,-991300.7,0,0,0,-0.3974535,-17863.11
4.774,-0.04769443,-19.50318,-993288.8,0,0,0,-0.3974535,-17898.94
4.79,-0.04793053,-19.53479,-994898.6,0,0,0,-0.3994211,-17927.95
4.804,-0.04816664,-19.57241,-996814.4,0,0,0,-0.4013887,-17962.47
4.816,-0.04816664,-19.61424,-998945.3,0,0,0,-0.4013887,-18000.87
4.826,-0.04840276,-19.65282,-1000910,0,0,0,-0.4033563,-18036.27
4.838,-0.04840276,-19.70495,-1003565,0,0,0,-0.4033563,-18084.11
4.85,-0.04863887,-19.75658,-1006194,0,0,0,-0.4053239,-18131.49
4.87,-0.04887498,-19.78713,-1007750,0,0,0,-0.4072915,-18159.53
4.892,-0.04887498,-19.82351,-1009603,0,0,0,-0.4072915,-18192.92
4.904,-0.04911109,-19.85672,-1011295,0,0,0,-0.4092591,-18223.4
4.916,-0.04911109,-19.89382,-1013184,0,0,0,-0.4092591,-18257.44
4.928,-0.0493472,-19.93833,-1015451,0,0,0,-0.4112267,-18298.29
4.94,-0.0493472,-19.99259,-1018214,0,0,0,-0.4112267,-18348.09
4.95,-0.04958331,-20.04177,-1020719,0,0,0,-0.4131942,-18393.22
4.964,-0.04958331,-20.08368,-1022854,0,0,0,-0.4131942,-18431.69
4.996,-0.05005554,-20.10885,-1024135,0,0,0,-0.4171295,-18454.79
5.008,-0.05005554,-20.15289,-1026379,0,0,0,-0.4171295,-18495.21
5.02,-0.05029164,-20.20627,-1029097,0,0,0,-0.419097,-18544.19
5.032,-0.05029164,-20.26253,-1031962,0,0,0,-0.419097,-18595.83
5.044,-0.05052776,-20.30399,-1034074,0,0,0,-0.4210646,-18633.88
5.056,-0.05052776,-20.3346,-1035633,0,0,0,-0.4210646,-18661.97
5.068,-0.05076387,-20.37341,-1037609,0,0,0,-0.4230323,-18697.58
5.08,-0.05076387,-20.41881,-1039922,0,0,0,-0.4230323,-18739.25
5.11,-0.05123609,-20.45554,-1041792,0,0,0,-0.4269674,-18772.96
5.122,-0.05123609,-20.50829,-1044479,0,0,0,-0.4269674,-18821.38
5.132,-0.0514722,-20.55309,-1046761,0,0,0,-0.428935,-18862.49
5.144,-0.0514722,-20.59235,-1048760,0,0,0,-0.428935,-18898.52
5.156,-0.05170831,-20.63278,-1050819,0,0,0,-0.4309026,-18935.62
5.168,-0.05170831,-20.6681,-1052618,0,0,0,-0.4309026,-18968.04
5.186,-0.05194442,-20.69726,-1054103,0,0,0,-0.4328702,-18994.8
5.198,-0.05194442,-20.73663,-1056108,0,0,0,-0.4328702,-19030.93
5.21,-0.05218054,-20.78308,-1058473,0,0,0,-0.4348378,-19073.55
5.222,-0.05218054,-20.81784,-1060244,0,0,0,-0.4348378,-19105.46
5.234,-0.05241664,-20.85369,-1062070,0,0,0,-0.4368054,-19138.36
5.246,-0.05241664,-20.90321,-1064592,0,0,0,-0.4368054,-19183.81
5.256,-0.05265275,-20.94235,-1066585,0,0,0,-0.4387729,-19219.73
5.272,-0.05288887,-20.97607,-1068302,0,0,0,-0.4407406,-19250.67
5.286,-0.05288887,-21.01227,-1070146,0,0,0,-0.4407406,-19283.9
5.296,-0.05312498,-21.05512,-1072329,0,0,0,-0.4427081,-19323.23
5.308,-0.05312498,-21.10414,-1074825,0,0,0,-0.4427081,-19368.21
5.326,-0.05336109,-21.13773,-1076536,0,0,0,-0.4446757,-19399.04
5.34,-0.05336109,-21.18671,-1079030,0,0,0,-0.4446757,-19443.99
5.35,-0.0535972,-21.22876,-1081172,0,0,0,-0.4466433,-19482.58
5.364,-0.0535972,-21.26765,-1083153,0,0,0,-0.4466433,-19518.27
5.38,-0.05383331,-21.2946,-1084525,0,0,0,-0.4486109,-19543.01
5.39,-0.05406942,-21.31998,-1085818,0,0,0,-0.4505785,-19566.29
5.404,-0.05406942,-21.35646,-1087676,0,0,0,-0.4505785,-19599.78
5.414,-0.05430553,-21.3877,-1089267,0,0,0,-0.4525461,-19628.45
5.426,-0.05430553,-21.42787,-1091312,0,0,0,-0.4525461,-19665.31
5.436,-0.05454164,-21.46101,-1093000,0,0,0,-0.4545137,-19695.73
5.448,-0.05454164,-21.4987,-1094920,0,0,0,-0.4545137,-19730.32
5.458,-0.05477776,-21.5377,-1096906,0,0,0,-0.4564813,-19766.1
5.47,-0.05477776,-21.59061,-1099601,0,0,0,-0.4564813,-19814.66
5.482,-0.05501387,-21.63493,-1101858,0,0,0,-0.4584489,-19855.34
5.504,-0.05524998,-21.66776,-1103530,0,0,0,-0.4604165,-19885.47
5.524,-0.05524998,-21.70996,-1105679,0,0,0,-0.4604165,-19924.2
5.534,-0.05548609,-21.75144,-1107792,0,0,0,-0.4623841,-19962.27
5.546,-0.05548609,-21.80009,-1110270,0,0,0,-0.4623841,-20006.92
5.558,-0.0557222,-21.84295,-1112453,0,0,0,-0.4643517,-20046.25
5.57,-0.0557222,-21.89116,-1114908,0,0,0,-0.4643517,-20090.5
5.58,-0.05595831,-21.92991,-1116881,0,0,0,-0.4663192,-20126.05
5.592,-0.05619442,-21.96187,-1118509,0,0,0,-0.4682868,-20155.39
5.612,-0.05619442,-21.99995,-1120448,0,0,0,-0.4682868,-20190.34
5.624,-0.05643053,-22.03677,-1122324,0,0,0,-0.4702544,-20224.13
5.636,-0.05643053,-22.0857,-1124816,0,0,0,-0.4702544,-20269.04
5.646,-0.05666664,-22.12354,-1126743,0,0,0,-0.472222,-20303.76
5.658,-0.05666664,-22.16211,-1128707,0,0,0,-0.472222,-20339.16
5.668,-0.05690275,-22.19588,-1130427,0,0,0,-0.4741896,-20370.15
5.68,-0.05690275,-22.24622,-1132991,0,0,0,-0.4741896,-20416.35
5.69,-0.05713886,-22.28359,-1134894,0,0,0,-0.4761572,-20450.64
5.704,-0.05737497,-22.31072,-1136276,0,0,0,-0.4781248,-20475.55
5.724,-0.05761109,-22.34072,-1137803,0,0,0,-0.4800924,-20503.07
5.736,-0.05761109,-22.38644,-1140132,0,0,0,-0.4800924,-20545.03
5.744,-0.05761109,-22.42665,-1142180,0,0,0,-0.4800924,-20581.94
5.75,-0.0578472,-22.46031,-1143894,0,0,0,-0.48206,-20612.83
5.758,-0.0578472,-22.50124,-1145979,0,0,0,-0.48206,-20650.39
5.77,-0.05808331,-22.54354,-1148133,0,0,0,-0.4840276,-20689.21
5.786,-0.05808331,-22.57864,-1149921,0,0,0,-0.4840276,-20721.43
5.796,-0.05831942,-22.60719,-1151375,0,0,0,-0.4859952,-20747.63
5.808,-0.05831942,-22.65392,-1153755,0,0,0,-0.4859952,-20790.52
5.818,-0.05855553,-22.69118,-1155653,0,0,0,-0.4879628,-20824.71
5.832,-0.05879164,-22.72623,-1157437,0,0,0,-0.4899304,-20856.87
5.846,-0.05879164,-22.76941,-1159637,0,0,0,-0.4899304,-20896.5
5.856,-0.05902775,-22.80506,-1161452,0,0,0,-0.4918979,-20929.22
5.868,-0.05902775,-22.84672,-1163574,0,0,0,-0.4918979,-20967.46
5.88,-0.05926386,-22.88176,-1165358,0,0,0,-0.4938655,-20999.61
5.892,-0.05926386,-22.91898,-1167254,0,0,0,-0.4938655,-21033.77
5.904,-0.05949998,-22.95126,-1168898,0,0,0,-0.4958331,-21063.4
5.916,-0.05949998,-22.98276,-1170502,0,0,0,-0.4958331,-21092.3
5.926,-0.05973608,-23.01217,-1172000,0,0,0,-0.4978007,-21119.29
5.938,-0.05973608,-23.04607,-1173727,0,0,0,-0.4978007,-21150.41
5.948,-0.05997219,-23.07268,-1175082,0,0,0,-0.4997683,-21174.83
5.96,-0.05997219,-23.10759,-1176860,0,0,0,-0.4997683,-21206.87
5.972,-0.05997219,-23.1483,-1178933,0,0,0,-0.4997683,-21244.22
5.982,-0.06020831,-23.18337,-1180720,0,0,0,-0.5017359,-21276.41
5.998,-0.06044442,-23.22035,-1182603,0,0,0,-0.5037035,-21310.35
6.012,-0.06044442,-23.25646,-1184442,0,0,0,-0.5037035,-21343.49
6.022,-0.06068053,-23.28784,-1186040,0,0,0,-0.5056711,-21372.29
6.04,-0.06068053,-23.32772,-1188071,0,0,0,-0.5056711,-21408.89
6.052,-0.06091664,-23.35669,-1189546,0,0,0,-0.5076387,-21435.47
6.062,-0.06091664,-23.40256,-1191883,0,0,0,-0.5076387,-21477.57
6.072,-0.06115275,-23.44777,-1194185,0,0,0,-0.5096063,-21519.07
6.086,-0.06115275,-23.48846,-1196257,0,0,0,-0.5096063,-21556.4
6.104,-0.06138886,-23.52684,-1198212,0,0,0,-0.5115739,-21591.63
6.116,-0.06138886,-23.56588,-1200201,0,0,0,-0.5115739,-21627.46
6.126,-0.06162497,-23.59829,-1201851,0,0,0,-0.5135415,-21657.2
6.138,-0.06162497,-23.63175,-1203555,0,0,0,-0.5135415,-21687.91
6.152,-0.06186108,-23.66666,-1205333,0,0,0,-0.515509,-21719.95
6.164,-0.06186108,-23.69883,-1206971,0,0,0,-0.515509,-21749.47
6.174,-0.0620972,-23.72807,-1208461,0,0,0,-0.5174766,-21776.3
6.186,-0.0620972,-23.76046,-1210110,0,0,0,-0.5174766,-21806.03
6.198,-0.06233331,-23.79736,-1211989,0,0,0,-0.5194442,-21839.89
6.21,-0.06233331,-23.83735,-1214026,0,0,0,-0.5194442,-21876.6
6.222,-0.06256942,-23.86741,-1215557,0,0,0,-0.5214118,-21904.18
6.236,-0.06280552,-23.90225,-1217332,0,0,0,-0.5233794,-21936.16
6.248,-0.06280552,-23.93979,-1219244,0,0,0,-0.5233794,-21970.61
6.258,-0.06304164,-23.97074,-1220820,0,0,0,-0.525347,-21999.01
6.27,-0.06304164,-24.00988,-1222813,0,0,0,-0.525347,-22034.93
6.28,-0.06327775,-24.05307,-1225013,0,0,0,-0.5273145,-22074.58
6.292,-0.06327775,-24.10299,-1227555,0,0,0,-0.5273145,-22120.39
6.304,-0.06351386,-24.13335,-1229102,0,0,0,-0.5292822,-22148.25
6.322,-0.06351386,-24.17337,-1231140,0,0,0,-0.5292822,-22184.98
6.334,-0.06374998,-24.2157,-1233295,0,0,0,-0.5312498,-22223.83
6.35,-0.06374998,-24.25243,-1235166,0,0,0,-0.5312498,-22257.54
6.366,-0.06398609,-24.28329,-1236738,0,0,0,-0.5332174,-22285.86
6.378,-0.0642222,-24.31978,-1238596,0,0,0,-0.535185,-22319.35
6.39,-0.0642222,-24.36378,-1240837,0,0,0,-0.535185,-22359.73
6.4,-0.0644583,-24.39755,-1242557,0,0,0,-0.5371525,-22390.72
6.412,-0.0644583,-24.44119,-1244780,0,0,0,-0.5371525,-22430.77
6.422,-0.06469441,-24.47565,-1246535,0,0,0,-0.5391201,-22462.39
6.434,-0.06469441,-24.50918,-1248242,0,0,0,-0.5391201,-22493.16
6.454,-0.06493053,-24.54375,-1250003,0,0,0,-0.5410877,-22524.89
6.468,-0.06493053,-24.57994,-1251846,0,0,0,-0.5410877,-22558.1
6.478,-0.06516664,-24.61679,-1253723,0,0,0,-0.5430554,-22591.93
6.49,-0.06516664,-24.653,-1255567,0,0,0,-0.5430554,-22625.15
6.5,-0.06540275,-24.68119,-1257003,0,0,0,-0.5450229,-22651.03
6.512,-0.06540275,-24.72365,-1259165,0,0,0,-0.5450229,-22689.99
6.522,-0.06563886,-24.76448,-1261245,0,0,0,-0.5469905,-22727.47
6.54,-0.06563886,-24.80097,-1263103,0,0,0,-0.5469905,-22760.95
6.552,-0.06587497,-24.82444,-1264299,0,0,0,-0.5489581,-22782.5
6.564,-0.06611108,-24.8639,-1266308,0,0,0,-0.5509257,-22818.71
6.576,-0.06611108,-24.89909,-1268100,0,0,0,-0.5509257,-22851
6.588,-0.06634719,-24.93666,-1270014,0,0,0,-0.5528933,-22885.49
6.6,-0.06634719,-24.98425,-1272437,0,0,0,-0.5528933,-22929.16
6.612,-0.06658331,-25.02167,-1274343,0,0,0,-0.5548609,-22963.5
6.626,-0.06658331,-25.05861,-1276225,0,0,0,-0.5548609,-22997.41
6.636,-0.06681942,-25.09194,-1277922,0,0,0,-0.5568284,-23027.99
6.648,-0.06681942,-25.13538,-1280134,0,0,0,-0.5568284,-23067.86
6.666,-0.06705553,-25.1695,-1281872,0,0,0,-0.5587961,-23099.17
6.68,-0.06705553,-25.21022,-1283946,0,0,0,-0.5587961,-23136.54
6.692,-0.06729164,-25.24727,-1285833,0,0,0,-0.5607637,-23170.54
6.708,-0.06752774,-25.28457,-1287733,0,0,0,-0.5627312,-23204.78
6.722,-0.06752774,-25.32659,-1289872,0,0,0,-0.5627312,-23243.34
6.732,-0.06776386,-25.36319,-1291737,0,0,0,-0.5646988,-23276.93
6.744,-0.06776386,-25.40078,-1293651,0,0,0,-0.5646988,-23311.43
6.762,-0.06799997,-25.43759,-1295526,0,0,0,-0.5666664,-23345.21
6.776,-0.06799997,-25.48108,-1297741,0,0,0,-0.5666664,-23385.12
6.788,-0.06823608,-25.52878,-1300170,0,0,0,-0.568634,-23428.9
6.8,-0.06823608,-25.57191,-1302367,0,0,0,-0.568634,-23468.48
6.816,-0.0684722,-25.60577,-1304091,0,0,0,-0.5706016,-23499.56
6.828,-0.0687083,-25.63804,-1305735,0,0,0,-0.5725692,-23529.17
6.844,-0.0687083,-25.67563,-1307649,0,0,0,-0.5725692,-23563.67
6.86,-0.06894442,-25.71283,-1309544,0,0,0,-0.5745368,-23597.81
6.872,-0.06894442,-25.74714,-1311291,0,0,0,-0.5745368,-23629.3
6.882,-0.06918052,-25.77783,-1312854,0,0,0,-0.5765043,-23657.46
6.894,-0.06918052,-25.81684,-1314841,0,0,0,-0.5765043,-23693.26
6.906,-0.06941664,-25.8597,-1317024,0,0,0,-0.578472,-23732.6
6.918,-0.06941664,-25.90234,-1319196,0,0,0,-0.578472,-23771.73
6.928,-0.06965275,-25.93019,-1320614,0,0,0,-0.5804396,-23797.29
6.94,-0.06965275,-25.96239,-1322254,0,0,0,-0.5804396,-23826.84
6.95,-0.06988886,-25.9928,-1323803,0,0,0,-0.5824072,-23854.75
6.97,-0.07012497,-26.02228,-1325304,0,0,0,-0.5843747,-23881.81
6.986,-0.07012497,-26.06343,-1327400,0,0,0,-0.5843747,-23919.57
6.994,-0.07036108,-26.10286,-1329408,0,0,0,-0.5863424,-23955.76
7.002,-0.07036108,-26.14276,-1331440,0,0,0,-0.5863424,-23992.38
7.016,-0.07036108,-26.18539,-1333611,0,0,0,-0.5863424,-24031.5
7.032,-0.0705972,-26.21018,-1334874,0,0,0,-0.58831,-24054.25
7.042,-0.0708333,-26.23739,-1336260,0,0,0,-0.5902776,-24079.22
7.054,-0.0708333,-26.27419,-1338134,0,0,0,-0.5902776,-24113
7.066,-0.07106941,-26.30471,-1339688,0,0,0,-0.5922451,-24141
7.078,-0.07106941,-26.34145,-1341559,0,0,0,-0.5922451,-24174.72
7.09,-0.07130553,-26.38469,-1343762,0,0,0,-0.5942127,-24214.41
7.102,-0.07130553,-26.42761,-1345947,0,0,0,-0.5942127,-24253.79
7.114,-0.07154164,-26.46443,-1347822,0,0,0,-0.5961803,-24287.58
7.128,-0.07154164,-26.49917,-1349592,0,0,0,-0.5961803,-24319.47
7.144,-0.07177775,-26.53453,-1351392,0,0,0,-0.5981479,-24351.92
7.16,-0.07177775,-26.57186,-1353294,0,0,0,-0.5981479,-24386.18
7.17,-0.07201386,-26.60801,-1355135,0,0,0,-0.6001155,-24419.36
7.182,-0.07201386,-26.65825,-1357694,0,0,0,-0.6001155,-24465.46
7.192,-0.07224997,-26.69778,-1359707,0,0,0,-0.6020831,-24501.74
7.204,-0.07224997,-26.73666,-1361687,0,0,0,-0.6020831,-24537.43
7.218,-0.07248608,-26.77313,-1363544,0,0,0,-0.6040506,-24570.9
7.234,-0.07272219,-26.79793,-1364807,0,0,0,-0.6060182,-24593.65
7.254,-0.07272219,-26.8383,-1366863,0,0,0,-0.6060182,-24630.7
7.262,-0.0729583,-26.87697,-1368833,0,0,0,-0.6079859,-24666.2
7.274,-0.0729583,-26.93155,-1371612,0,0,0,-0.6079859,-24716.28
7.284,-0.07319441,-26.96171,-1373149,0,0,0,-0.6099535,-24743.96
7.296,-0.07319441,-26.99303,-1374744,0,0,0,-0.6099535,-24772.71
7.306,-0.07343053,-27.02569,-1376407,0,0,0,-0.6119211,-24802.68
7.318,-0.07343053,-27.0647,-1378394,0,0,0,-0.6119211,-24838.48
7.334,-0.07366664,-27.10002,-1380193,0,0,0,-0.6138886,-24870.9
7.35,-0.07366664,-27.13611,-1382031,0,0,0,-0.6138886,-24904.02
7.36,-0.07390274,-27.16905,-1383708,0,0,0,-0.6158562,-24934.24
7.372,-0.07390274,-27.21622,-1386111,0,0,0,-0.6158562,-24977.54
7.384,-0.07413886,-27.26801,-1388748,0,0,0,-0.6178238,-25025.06
7.396,-0.07413886,-27.31537,-1391160,0,0,0,-0.6178238,-25068.53
7.408,-0.07437497,-27.35631,-1393246,0,0,0,-0.6197914,-25106.11
7.422,-0.07461108,-27.38739,-1394828,0,0,0,-0.621759,-25134.63
7.444,-0.07461108,-27.42599,-1396794,0,0,0,-0.621759,-25170.05
7.456,-0.07484719,-27.46464,-1398763,0,0,0,-0.6237266,-25205.53
7.468,-0.07484719,-27.51359,-1401256,0,0,0,-0.6237266,-25250.45
7.478,-0.0750833,-27.55265,-1403245,0,0,0,-0.6256942,-25286.29
7.49,-0.0750833,-27.59109,-1405203,0,0,0,-0.6256942,-25321.58
7.502,-0.07531942,-27.62083,-1406717,0,0,0,-0.6276618,-25348.87
7.52,-0.07555552,-27.65542,-1408479,0,0,0,-0.6296294,-25380.61
7.534,-0.07555552,-27.69136,-1410309,0,0,0,-0.6296294,-25413.59
7.546,-0.07579163,-27.72191,-1411865,0,0,0,-0.6315969,-25441.63
7.558,-0.07579163,-27.75753,-1413679,0,0,0,-0.6315969,-25474.32
7.57,-0.07602775,-27.80346,-1416019,0,0,0,-0.6335645,-25516.47
7.582,-0.07602775,-27.85177,-1418479,0,0,0,-0.6335645,-25560.81
7.594,-0.07626386,-27.88523,-1420183,0,0,0,-0.6355321,-25591.52
7.606,-0.07626386,-27.92175,-1422043,0,0,0,-0.6355321,-25625.04
7.616,-0.07649997,-27.95162,-1423565,0,0,0,-0.6374997,-25652.45
7.628,-0.07649997,-27.98356,-1425191,0,0,0,-0.6374997,-25681.76
7.642,-0.07673609,-28.0138,-1426731,0,0,0,-0.6394674,-25709.51
7.654,-0.07673609,-28.05933,-1429050,0,0,0,-0.6394674,-25751.29
7.666,-0.07697219,-28.11121,-1431692,0,0,0,-0.6414349,-25798.91
7.678,-0.07697219,-28.15375,-1433859,0,0,0,-0.6414349,-25837.95
7.692,-0.0772083,-28.18459,-1435430,0,0,0,-0.6434025,-25866.26
7.708,-0.0772083,-28.21841,-1437152,0,0,0,-0.6434025,-25897.29
7.72,-0.07744441,-28.257,-1439117,0,0,0,-0.6453701,-25932.71
7.732,-0.07744441,-28.29564,-1441085,0,0,0,-0.6453701,-25968.17
7.748,-0.07768052,-28.32846,-1442757,0,0,0,-0.6473377,-25998.29
7.76,-0.07768052,-28.36783,-1444762,0,0,0,-0.6473377,-26034.42
7.77,-0.07791664,-28.40695,-1446754,0,0,0,-0.6493053,-26070.32
7.782,-0.07791664,-28.4504,-1448967,0,0,0,-0.6493053,-26110.2
7.798,-0.07815275,-28.48857,-1450911,0,0,0,-0.651273,-26145.23
7.81,-0.07815275,-28.52006,-1452515,0,0,0,-0.651273,-26174.13
7.82,-0.07838886,-28.54753,-1453914,0,0,0,-0.6532405,-26199.34
7.838,-0.07838886,-28.58308,-1455725,0,0,0,-0.6532405,-26231.97
7.852,-0.07862496,-28.61535,-1457368,0,0,0,-0.655208,-26261.58
7.864,-0.07862496,-28.65493,-1459384,0,0,0,-0.655208,-26297.91
7.876,-0.07886108,-28.69663,-1461507,0,0,0,-0.6571757,-26336.17
7.888,-0.07886108,-28.74328,-1463883,0,0,0,-0.6571757,-26378.99
7.898,-0.07909719,-28.77321,-1465408,0,0,0,-0.6591433,-26406.46
7.912,-0.07909719,-28.80765,-1467162,0,0,0,-0.6591433,-26438.06
7.926,-0.0793333,-28.84251,-1468937,0,0,0,-0.6611109,-26470.06
7.94,-0.0793333,-28.87974,-1470833,0,0,0,-0.6611109,-26504.23
7.958,-0.07956942,-28.90736,-1472240,0,0,0,-0.6630785,-26529.58
7.972,-0.07956942,-28.9417,-1473989,0,0,0,-0.6630785,-26561.09
7.982,-0.07980552,-28.97496,-1475683,0,0,0,-0.665046,-26591.62
7.994,-0.07980552,-29.01645,-1477796,0,0,0,-0.665046,-26629.69
8.004,-0.08004164,-29.04342,-1479169,0,0,0,-0.6670136,-26654.44
8.018,-0.08004164,-29.07841,-1480951,0,0,0,-0.6670136,-26686.55
8.034,-0.08027774,-29.11985,-1483062,0,0,0,-0.6689812,-26724.58
8.046,-0.08027774,-29.16569,-1485397,0,0,0,-0.6689812,-26766.66
8.056,-0.08051386,-29.20401,-1487348,0,0,0,-0.6709488,-26801.82
8.068,-0.08051386,-29.24954,-1489667,0,0,0,-0.6709488,-26843.61
8.078,-0.08074997,-29.28648,-1491548,0,0,0,-0.6729164,-26877.51
8.09,-0.08098608,-29.32866,-1493697,0,0,0,-0.674884,-26916.22
8.102,-0.08098608,-29.36586,-1495591,0,0,0,-0.674884,-26950.36
8.112,-0.08122219,-29.39431,-1497040,0,0,0,-0.6768516,-26976.47
8.124,-0.08122219,-29.4325,-1498985,0,0,0,-0.6768516,-27011.51
8.134,-0.0814583,-29.46504,-1500642,0,0,0,-0.6788192,-27041.38
8.146,-0.0814583,-29.51101,-1502984,0,0,0,-0.6788192,-27083.57
8.156,-0.08169441,-29.54407,-1504667,0,0,0,-0.6807867,-27113.91
8.168,-0.08169441,-29.5821,-1506604,0,0,0,-0.6807867,-27148.82
8.178,-0.08193052,-29.61567,-1508314,0,0,0,-0.6827543,-27179.63
8.19,-0.08193052,-29.66128,-1510637,0,0,0,-0.6827543,-27221.48
8.202,-0.08216663,-29.70636,-1512933,0,0,0,-0.6847219,-27262.86
8.216,-0.08216663,-29.74156,-1514725,0,0,0,-0.6847219,-27295.15
8.236,-0.08240275,-29.77495,-1516426,0,0,0,-0.6866896,-27325.8
8.248,-0.08263885,-29.81876,-1518657,0,0,0,-0.6886571,-27366.01
8.26,-0.08263885,-29.87188,-1521362,0,0,0,-0.6886571,-27414.75
8.27,-0.08287497,-29.91053,-1523331,0,0,0,-0.6906247,-27450.22
8.282,-0.08287497,-29.95276,-1525481,0,0,0,-0.6906247,-27488.98
8.292,-0.08311108,-29.98741,-1527246,0,0,0,-0.6925923,-27520.79
8.304,-0.08311108,-30.02703,-1529264,0,0,0,-0.6925923,-27557.14
8.316,-0.08334719,-30.05792,-1530838,0,0,0,-0.6945599,-27585.5
8.328,-0.08334719,-30.09533,-1532743,0,0,0,-0.6945599,-27619.82
8.338,-0.0835833,-30.12826,-1534420,0,0,0,-0.6965275,-27650.05
8.35,-0.0835833,-30.16481,-1536281,0,0,0,-0.6965275,-27683.59
8.362,-0.08381941,-30.19988,-1538067,0,0,0,-0.6984951,-27715.78
8.374,-0.08381941,-30.23771,-1539994,0,0,0,-0.6984951,-27750.5
8.386,-0.08405552,-30.27921,-1542108,0,0,0,-0.7004626,-27788.58
8.398,-0.08405552,-30.31962,-1544166,0,0,0,-0.7004626,-27825.67
8.412,-0.08429163,-30.35548,-1545992,0,0,0,-0.7024302,-27858.58
8.428,-0.08429163,-30.39388,-1547948,0,0,0,-0.7024302,-27893.82
8.44,-0.08452775,-30.42798,-1549684,0,0,0,-0.7043979,-27925.11
8.452,-0.08452775,-30.46755,-1551699,0,0,0,-0.7043979,-27961.43
8.464,-0.08452775,-30.50201,-1553455,0,0,0,-0.7043979,-27993.06
8.476,-0.08476386,-30.5316,-1554962,0,0,0,-0.7063655,-28020.21
8.49,-0.08499997,-30.56282,-1556552,0,0,0,-0.708333,-28048.86
8.504,-0.08499997,-30.59972,-1558431,0,0,0,-0.708333,-28082.72
8.516,-0.08523608,-30.64565,-1560770,0,0,0,-0.7103007,-28124.88
8.528,-0.08523608,-30.6867,-1562861,0,0,0,-0.7103007,-28162.55
8.54,-0.08547218,-30.71996,-1564555,0,0,0,-0.7122682,-28193.08
8.554,-0.08547218,-30.75758,-1566471,0,0,0,-0.7122682,-28227.6
8.564,-0.0857083,-30.78752,-1567996,0,0,0,-0.7142358,-28255.08
8.58,-0.0857083,-30.82235,-1569770,0,0,0,-0.7142358,-28287.05
8.59,-0.08594441,-30.85288,-1571324,0,0,0,-0.7162035,-28315.07
8.602,-0.08594441,-30.90746,-1574104,0,0,0,-0.7162035,-28365.15
8.614,-0.08618053,-30.95552,-1576552,0,0,0,-0.7181711,-28409.26
8.628,-0.08618053,-30.99114,-1578366,0,0,0,-0.7181711,-28441.95
8.64,-0.08641663,-31.02728,-1580206,0,0,0,-0.7201386,-28475.12
8.652,-0.08641663,-31.07643,-1582710,0,0,0,-0.7201386,-28520.23
8.664,-0.08665274,-31.12004,-1584931,0,0,0,-0.7221062,-28560.25
8.678,-0.08688885,-31.14813,-1586361,0,0,0,-0.7240738,-28586.03
8.698,-0.08688885,-31.18369,-1588172,0,0,0,-0.7240738,-28618.66
8.71,-0.08712496,-31.23098,-1590581,0,0,0,-0.7260414,-28662.06
8.722,-0.08736108,-31.28225,-1593192,0,0,0,-0.728009,-28709.12
8.734,-0.08736108,-31.33095,-1595672,0,0,0,-0.728009,-28753.81
8.746,-0.08759719,-31.37699,-1598017,0,0,0,-0.7299766,-28796.06
8.758,-0.08759719,-31.41668,-1600038,0,0,0,-0.7299766,-28832.49
8.77,-0.0878333,-31.44823,-1601645,0,0,0,-0.7319442,-28861.44
8.784,-0.0878333,-31.48644,-1603592,0,0,0,-0.7319442,-28896.51
8.794,-0.08806941,-31.51571,-1605082,0,0,0,-0.7339118,-28923.38
8.808,-0.08806941,-31.55118,-1606889,0,0,0,-0.7339118,-28955.93
8.82,-0.08830551,-31.58985,-1608858,0,0,0,-0.7358793,-28991.41
8.832,-0.08830551,-31.63566,-1611191,0,0,0,-0.7358793,-29033.45
8.844,-0.08854163,-31.68094,-1613497,0,0,0,-0.7378469,-29075.01
8.856,-0.08854163,-31.72233,-1615605,0,0,0,-0.7378469,-29113
8.866,-0.08877774,-31.75338,-1617186,0,0,0,-0.7398145,-29141.49
8.886,-0.08877774,-31.78938,-1619020,0,0,0,-0.7398145,-29174.53
8.9,-0.08901386,-31.81771,-1620463,0,0,0,-0.7417821,-29200.53
8.912,-0.08901386,-31.86271,-1622755,0,0,0,-0.7417821,-29241.83
8.922,-0.08924997,-31.90695,-1625008,0,0,0,-0.7437497,-29282.44
8.934,-0.08924997,-31.95237,-1627321,0,0,0,-0.7437497,-29324.12
8.946,-0.08948608,-31.98661,-1629065,0,0,0,-0.7457173,-29355.53
8.958,-0.08948608,-32.02349,-1630943,0,0,0,-0.7457173,-29389.38
8.974,-0.08972218,-32.05581,-1632589,0,0,0,-0.7476848,-29419.05
8.994,-0.08995829,-32.08872,-1634265,0,0,0,-0.7496524,-29449.25
9.006,-0.08995829,-32.12916,-1636325,0,0,0,-0.7496524,-29486.37
9.018,-0.09019441,-32.1793,-1638878,0,0,0,-0.7516201,-29532.38
9.03,-0.09019441,-32.22857,-1641388,0,0,0,-0.7516201,-29577.59
9.04,-0.09043052,-32.27593,-1643800,0,0,0,-0.7535877,-29621.06
9.052,-0.09043052,-32.32552,-1646326,0,0,0,-0.7535877,-29666.58
9.062,-0.09066664,-32.35528,-1647841,0,0,0,-0.7555553,-29693.88
9.076,-0.09066664,-32.38995,-1649607,0,0,0,-0.7555553,-29725.7
9.09,-0.09090274,-32.41792,-1651031,0,0,0,-0.7575228,-29751.37
9.102,-0.09113885,-32.44616,-1652470,0,0,0,-0.7594904,-29777.29
9.114,-0.09113885,-32.49136,-1654771,0,0,0,-0.7594904,-29818.77
9.124,-0.09137496,-32.53464,-1656976,0,0,0,-0.761458,-29858.49
9.136,-0.09137496,-32.58391,-1659485,0,0,0,-0.761458,-29903.71
9.148,-0.09161107,-32.62387,-1661520,0,0,0,-0.7634256,-29940.38
9.16,-0.09161107,-32.65958,-1663339,0,0,0,-0.7634256,-29973.15
9.172,-0.09184719,-32.69755,-1665273,0,0,0,-0.7653932,-30008
9.184,-0.09184719,-32.73405,-1667131,0,0,0,-0.7653932,-30041.5
9.196,-0.09208329,-32.76,-1668453,0,0,0,-0.7673607,-30065.31
9.216,-0.09208329,-32.7985,-1670414,0,0,0,-0.7673607,-30100.64
9.226,-0.09231941,-32.83279,-1672161,0,0,0,-0.7693284,-30132.12
9.238,-0.09231941,-32.88281,-1674708,0,0,0,-0.7693284,-30178.02
9.25,-0.09255552,-32.91861,-1676531,0,0,0,-0.771296,-30210.87
9.262,-0.09255552,-32.96194,-1678738,0,0,0,-0.771296,-30250.64
9.272,-0.09279162,-32.99929,-1680640,0,0,0,-0.7732635,-30284.92
9.288,-0.09302774,-33.03614,-1682517,0,0,0,-0.7752311,-30318.73
9.306,-0.09302774,-33.0766,-1684578,0,0,0,-0.7752311,-30355.87
9.316,-0.09326385,-33.11609,-1686589,0,0,0,-0.7771988,-30392.12
9.328,-0.09326385,-33.1613,-1688891,0,0,0,-0.7771988,-30433.61
9.34,-0.09349996,-33.19657,-1690687,0,0,0,-0.7791663,-30465.97
9.352,-0.09349996,-33.24078,-1692939,0,0,0,-0.7791663,-30506.55
9.364,-0.09373607,-33.29145,-1695520,0,0,0,-0.7811339,-30553.05
9.378,-0.09373607,-33.33045,-1697506,0,0,0,-0.7811339,-30588.84
9.392,-0.09397218,-33.36569,-1699301,0,0,0,-0.7831016,-30621.18
9.408,-0.09397218,-33.40164,-1701132,0,0,0,-0.7831016,-30654.17
9.422,-0.09420829,-33.43337,-1702747,0,0,0,-0.7850691,-30683.29
9.434,-0.0944444,-33.47282,-1704757,0,0,0,-0.7870367,-30719.5
9.446,-0.0944444,-33.52447,-1707387,0,0,0,-0.7870367,-30766.9
9.458,-0.09468052,-33.57797,-1710112,0,0,0,-0.7890043,-30816
9.474,-0.09468052,-33.6115,-1711820,0,0,0,-0.7890043,-30846.77
9.488,-0.09491662,-33.63741,-1713139,0,0,0,-0.7909719,-30870.55
9.5,-0.09491662,-33.67808,-1715210,0,0,0,-0.7909719,-30907.87
9.51,-0.09515274,-33.712,-1716938,0,0,0,-0.7929395,-30939.01
9.522,-0.09515274,-33.75112,-1718931,0,0,0,-0.7929395,-30974.91
9.532,-0.09538885,-33.78414,-1720612,0,0,0,-0.7949071,-31005.21
9.544,-0.09538885,-33.83034,-1722965,0,0,0,-0.7949071,-31047.62
9.556,-0.09562496,-33.86743,-1724854,0,0,0,-0.7968747,-31081.65
9.568,-0.09562496,-33.90821,-1726931,0,0,0,-0.7968747,-31119.07
9.578,-0.09586107,-33.94905,-1729011,0,0,0,-0.7988423,-31156.55
9.59,-0.09586107,-33.9956,-1731382,0,0,0,-0.7988423,-31199.28
9.604,-0.09609718,-34.02829,-1733047,0,0,0,-0.8008099,-31229.28
9.62,-0.09633329,-34.06648,-1734991,0,0,0,-0.8027774,-31264.32
9.632,-0.09633329,-34.10495,-1736951,0,0,0,-0.8027774,-31299.63
9.644,-0.0965694,-34.14388,-1738934,0,0,0,-0.804745,-31335.36
9.656,-0.0965694,-34.17771,-1740657,0,0,0,-0.804745,-31366.41
9.666,-0.09680552,-34.2081,-1742204,0,0,0,-0.8067126,-31394.3
9.678,-0.09680552,-34.25213,-1744447,0,0,0,-0.8067126,-31434.71
9.69,-0.09704163,-34.29629,-1746696,0,0,0,-0.8086802,-31475.24
9.704,-0.09704163,-34.33236,-1748533,0,0,0,-0.8086802,-31508.34
9.72,-0.09727774,-34.3652,-1750205,0,0,0,-0.8106478,-31538.48
9.732,-0.09727774,-34.40468,-1752216,0,0,0,-0.8106478,-31574.71
9.744,-0.09751385,-34.44356,-1754196,0,0,0,-0.8126154,-31610.39
9.756,-0.09751385,-34.48312,-1756211,0,0,0,-0.8126154,-31646.69
9.766,-0.09774995,-34.52214,-1758198,0,0,0,-0.8145829,-31682.51
9.778,-0.09774995,-34.5694,-1760605,0,0,0,-0.8145829,-31725.88
9.79,-0.09798607,-34.60601,-1762470,0,0,0,-0.8165506,-31759.48
9.804,-0.09798607,-34.64095,-1764249,0,0,0,-0.8165506,-31791.55
9.818,-0.09822218,-34.66642,-1765546,0,0,0,-0.8185182,-31814.92
9.834,-0.09845829,-34.70743,-1767635,0,0,0,-0.8204858,-31852.55
9.844,-0.09845829,-34.75516,-1770066,0,0,0,-0.8204858,-31896.36
9.85,-0.09845829,-34.78678,-1771676,0,0,0,-0.8204858,-31925.38
9.86,-0.09869441,-34.83106,-1773932,0,0,0,-0.8224534,-31966.02
9.876,-0.09869441,-34.86919,-1775873,0,0,0,-0.8224534,-32001.01
9.888,-0.09893051,-34.90137,-1777512,0,0,0,-0.8244209,-32030.54
9.9,-0.09916662,-34.94322,-1779644,0,0,0,-0.8263885,-32068.95
9.912,-0.09916662,-34.98174,-1781605,0,0,0,-0.8263885,-32104.3
9.932,-0.09940273,-35.01125,-1783108,0,0,0,-0.8283561,-32131.39
9.946,-0.09963885,-35.05695,-1785436,0,0,0,-0.8303237,-32173.33
9.958,-0.09963885,-35.10597,-1787932,0,0,0,-0.8303237,-32218.31
9.968,-0.09987496,-35.14142,-1789738,0,0,0,-0.8322913,-32250.85
9.98,-0.09987496,-35.18438,-1791926,0,0,0,-0.8322913,-32290.27
9.992,-0.1001111,-35.22717,-1794105,0,0,0,-0.834259,-32329.55